Workbook

Sheet IBM Forecast T&M - AP07
A1: Billing Period Start Date | B1: 46202 | J1: HELP
A2: Billing Period End Date | B2: 46227
A3: Invoice Date | B3: 46246
A4: Billing Weeks | B4: 4 WEEKS
I6: Forecast AP07 | M6: Actuals AP07
H7: Values
A8: PO Owner | B8: PO# | C8: ProjectName | D8: ResourceName | E8: BillRate | F8: Location | G8: Comments | H8: ForecastedHours | I8: ForecastFee | J8: ForecastExpenses | K8: ForecastTotalFee | L8: ActualHours | M8: ActualFee | N8: ActualExpenses | O8: ActualTotalFee | P8: Accuracy | Q8: Expense %
A9: (blank) | B9: (blank) | C9: (blank) | D9: (blank) | E9: (blank) | F9: (blank) | G9: (blank)
B10: 9501219264 | C10: TPM - Transformation PM Support Ireland 2026 | D10: EAMONN KEATING | E10: 154 | F10: Onshore | G10: (blank) | H10: 184 | I10: 28336 | J10: 0 | K10: 28336 | M10: 0 | N10: 0 | O10: 0 | P10: 1 | Q10: 0
B11: 9501287494 | C11: SAP Concur (PT&E) Enhancement Germany Travel Allowance | D11: Sridharan K | E11: 61.75 | F11: Offshore | G11: (blank) | H11: 66 | I11: 4075.5 | J11: 0 | K11: 4075.5 | M11: 0 | N11: 0 | O11: 0 | P11: 1 | Q11: 0
A12: David McGettigan | B12: 9500905777/9501153096 | C12: SAP Application Managed Service - SAP BI Factory | D12: SHRUTI BIRE | E12: 29 | F12: Offshore | G12: (blank) | H12: 0 | I12: 0 | J12: 0 | K12: 0 | M12: 0 | N12: 0 | O12: 0 | P12: 1 | Q12: 0
D13: B MANOHAR | H13: 0 | I13: 0 | J13: 0 | K13: 0 | M13: 0 | N13: 0 | O13: 0 | P13: 1 | Q13: 0
C14: SAP Application Managed Service - SAP BI PCR 02 | D14: (blank) | E14: 47.5 | F14: Offshore | G14: (blank) | H14: 0 | I14: 0 | J14: 0 | K14: 0 | M14: 0 | N14: 0 | O14: 0 | P14: 1 | Q14: 0
C15: SAP Application Managed Service - SAP BI PCR 03 | D15: LAKSHMAN VATTURI | E15: 42.5 | F15: Offshore | G15: (blank) | H15: 0 | I15: 0 | J15: 0 | K15: 0 | M15: 0 | N15: 0 | O15: 0 | P15: 1 | Q15: 0
A16: Okan Serbest | B16: 9501070761 | C16: SAP Dalian Takeback | D16: TBD | E16: 84.5 | F16: (blank) | G16: (blank) | H16: 342 | I16: 28899 | J16: 0 | K16: 28899 | M16: 0 | N16: 0 | O16: 0 | P16: 2 | Q16: 0
D17: Hema Ghildiyal | E17: 61.75 | F17: (blank) | G17: (blank) | H17: 0 | I17: 0 | J17: 0 | K17: 0 | M17: 0 | N17: 0 | O17: 0 | P17: 1 | Q17: 0
D18: RAJAMALLU AMARAGONDA | E18: 47.5 | F18: (blank) | G18: (blank) | H18: 0 | I18: 0 | J18: 0 | K18: 0 | M18: 0 | N18: 0 | O18: 0 | P18: 1 | Q18: 0
D19: SANTOSH BAKALKAR | E19: 47.5 | F19: Offshore | G19: (blank) | H19: 0 | I19: 0 | J19: 0 | K19: 0 | M19: 0 | N19: 0 | O19: 0 | P19: 1 | Q19: 0
D20: AKHAND SINGH | E20: 47.5 | F20: (blank) | G20: (blank) | H20: 0 | I20: 0 | J20: 0 | K20: 0 | M20: 0 | N20: 0 | O20: 0 | P20: 1 | Q20: 0
D21: ASHLYN DSILVA | E21: 61.75 | F21: (blank) | G21: (blank) | H21: 0 | I21: 0 | J21: 0 | K21: 0 | M21: 0 | N21: 0 | O21: 0 | P21: 1 | Q21: 0
D22: KAVIN RAVI | E22: 47.5 | F22: (blank) | G22: (blank) | H22: 0 | I22: 0 | J22: 0 | K22: 0 | M22: 0 | N22: 0 | O22: 0 | P22: 1 | Q22: 0
D23: PRABHAKAR DHARMALA | E23: 61.75 | F23: (blank) | G23: (blank) | H23: 0 | I23: 0 | J23: 0 | K23: 0 | M23: 0 | N23: 0 | O23: 0 | P23: 1 | Q23: 0
D24: USHA KONGARA | E24: 47.5 | F24: (blank) | G24: (blank) | H24: 103.5 | I24: 4916.25 | J24: 0 | K24: 4916.25 | M24: 0 | N24: 0 | O24: 0 | P24: 1 | Q24: 0
D25: XIAO GUANG QUAN | E25: 84.5 | F25: (blank) | G25: (blank) | H25: 80 | I25: 6760 | J25: 0 | K25: 6760 | M25: 0 | N25: 0 | O25: 0 | P25: 1 | Q25: 0
D26: ARINDAM SINHA | E26: 61.75 | F26: (blank) | G26: (blank) | H26: 0 | I26: 0 | J26: 0 | K26: 0 | M26: 0 | N26: 0 | O26: 0 | P26: 1 | Q26: 0
D27: KIRANMAYEE DODLA | E27: 61.75 | F27: (blank) | G27: (blank) | H27: 0 | I27: 0 | J27: 0 | K27: 0 | M27: 0 | N27: 0 | O27: 0 | P27: 1 | Q27: 0
D28: Tony Ouyang | E28: 84.5 | F28: (blank) | G28: (blank) | H28: 171 | I28: 14449.5 | J28: 0 | K28: 14449.5 | M28: 0 | N28: 0 | O28: 0 | P28: 1 | Q28: 0
... D30: AMOL SHITOLE | E30: 61.75 | F30: (blank) | G30: (blank) | H30: 0 | I30: 0 | J30: 0 | K30: 0 | M30: 0 | N30: 0 | O30: 0 | P30: 1 | Q30: 0
C31: SAP Dalian Takeback $0 PCR | D31: LAURA DEININGER | E31: 265 | F31: Onshore | G31: (blank) | H31: 0 | I31: 0 | J31: 0 | K31: 0 | M31: 0 | N31: 0 | O31: 0 | P31: 1 | Q31: 0
D32: Dolly Osoba | E32: 307 | F32: Onshore | G32: (blank) | H32: 0 | I32: 0 | J32: 0 | K32: 0 | M32: 0 | N32: 0 | O32: 0 | P32: 1 | Q32: 0
B33: 9501140293 | C33: SAP FIN ACD 1H 2026 | D33: Swapan Sharma | E33: 205 | F33: Onshore | G33: (blank) | H33: 0 | I33: 0 | J33: 0 | K33: 0 | M33: 0 | N33: 0 | O33: 0 | P33: 1 | Q33: 0
D34: Prakash Thimmaiah | E34: 61.75 | F34: Offshore | G34: (blank) | H34: 0 | I34: 0 | J34: 0 | K34: 0 | M34: 0 | N34: 0 | O34: 0 | P34: 1 | Q34: 0
B35: 9501210950 | C35: Matsera ACD 1H 2026 Support | D35: Dolly Osoba | E35: 307 | F35: Onshore | G35: (blank) | H35: 0 | I35: 0 | J35: 0 | K35: 0 | M35: 0 | N35: 0 | O35: 0 | P35: 1 | Q35: 0
B36: 9501269309 | C36: FIN ACD 2H 2026 | D36: Swapan Sharma | E36: 205 | F36: Onshore | G36: (blank) | H36: 152 | I36: 31160 | J36: 0 | K36: 31160 | M36: 0 | N36: 0 | O36: 0 | P36: 1 | Q36: 0
D37: Prakash Thimmaiah | E37: 61.75 | F37: Offshore | G37: (blank) | H37: 171 | I37: 10559.25 | J37: 0 | K37: 10559.25 | M37: 0 | N37: 0 | O37: 0 | P37: 1 | Q37: 0
A38: Rajesh Hase | B38: 9501003131 | C38: SAP Brazil DRC Implementation | D38: TBD | E38: 47.5 | F38: Offshore | G38: (blank) | H38: 0 | I38: 0 | J38: 0 | K38: 0 | M38: 0 | N38: 0 | O38: 0 | P38: 3 | Q38: 0
D39: VENKATESULU THUMMALA | E39: 157 | F39: Onshore | G39: (blank) | H39: 0 | I39: 0 | J39: 0 | K39: 0 | M39: 0 | N39: 0 | O39: 0 | P39: 2 | Q39: 0
D40: CHANDRA JONNAGEDDALA | E40: 183 | F40: Onshore | G40: (blank) | H40: 0 | I40: 0 | J40: 0 | K40: 0 | M40: 0 | N40: 0 | O40: 0 | P40: 2 | Q40: 0
D41: VENKATESWARLU BASU | E41: 47.5 | F41: Offshore | G41: (blank) | H41: 0 | I41: 0 | J41: 0 | K41: 0 | M41: 0 | N41: 0 | O41: 0 | P41: 1 | Q41: 0
B42: 9501049922 | C42: SAP Agentic AI Implementation Delivery Team | D42: SANTHOSH R | E42: 61.75 | F42: Offshore | G42: (blank) | H42: 0 | I42: 0 | J42: 0 | K42: 0 | M42: 0 | N42: 0 | O42: 0 | P42: 1 | Q42: 0
...

Sheet IBM Forecast FP - AP07
A1: Billing Period Start Date | B1: ='IBM Forecast T&M - AP07'!B1 -> 46202
A2: Billing Period End Date | B2: ='IBM Forecast T&M - AP07'!B2 -> 46227
A3: Invoice Date | B3: ='IBM Forecast T&M - AP07'!B3 -> 46246
A4: Billing Weeks# | B4: ='IBM Forecast T&M - AP07'!B4 -> 4 WEEKS
A5: Pfizer Requested PO | B5: (All)
E6: Forecast AP07 | H6: Actuals AP07
E7: Values
A8: PO Owner | B8: PO # | C8: Project Name | D8: IBM PMA | E8: Forecast Fee $ | F8: Forecast Expenses $ | G8: Forecast Total $ | H8: Acual Fee $ | I8: Actual Expenses $ | J8: Actual Total $ | K8: Monthly Variance | L8: Forecast Accuracy | M8: Expense %
A9: Lynn Dehart | B9: 9501027309 | C9: Agentic AI Microsoft Dynamics - Extension | D9: Mansi | E9: 0 | G9: 0 | J9: 0 | K9: 0 | L9: 1 | M9: 0
C10: Agentic AI Microsoft Dynamics - PCR 2 | D10: Mansi | E10: 0 | G10: 0 | J10: 0 | K10: 0 | L10: 1 | M10: 0
A11: Andrew Alman | B11: 9501021314 | C11: Pfizer Serialization SAP ATTP/ICH 2025 2H Support | D11: Jaspal Singh | E11: 0 | G11: 0 | J11: 0 | K11: 0 | L11: 17 | M11: 0
A12: Jerome Robertson | B12: Pending PO | C12: BI AMS DI Support 2H 2026 | D12: Raju Parkala | E12: 9405 | G12: 9405 | J12: 0 | K12: -9405 | L12: 1 | M12: 0
B13: 9501160948 | C13: HBU IBP US Demand planning data ingestion to PGS UDH | D13: Jaspal Singh | E13: 0 | G13: 0 | J13: 0 | K13: 0 | L13: 1 | M13: 0
B14: 9501168669 | C14: BI: Network analytics APO CI | D14: Jaspal Singh | E14: 0 | G14: 0 | J14: 0 | K14: 0 | L14: 1 | M14: 0
B15: 9501168256 | C15: BI: Network analytics 1st Half 2026 | D15: Jaspal Singh | E15: 0 | G15: 0 | J15: 0 | K15: 0 | L15: 1 | M15: 0
B16: 9501143203 | C16: SAP Analytics Foundation - BDC-DataSphere Discovery | D16: Jaspal Singh | E16: 0 | G16: 0 | J16: 0 | K16: 0 | L16: 1 | M16: 0
A17: (blank) | B17: (blank) | C17: (blank) | D17: (blank)
B18: 9501142865 | C18: PGS Value Optimization- Project Manager- IT EOSL Device Remediation-2026 Kalmazoo MI ss | D18: Gagan | E18: 19066.67 | G18: 19066.67 | J18: 0 | K18: -19066.67 | L18: 1 | M18: 0
B19: 9501131945 | C19: Pfizer Value Optimization – 06 DSN 01 | D19: Gagan | E19: 45980 | G19: 45980 | J19: 0 | K19: -45980 | L19: 3 | M19: 0
B20: 9501173686 | C20: Network Security Engineer | D20: Gagan | E20: 19933 | G20: 19933 | J20: 0 | K20: -19933 | L20: 1 | M20: 0
B21: 9501179464 | C21: Catalyst Project - Onshore | D21: Gagan | E21: 0 | G21: 0 | J21: 0 | K21: 0 | L21: 2 | M21: 0
B22: PO Pending | C22: Consulting Services for Pfizer Counsel Related to DOJ Data Security Program Lead | D22: Mansi | E22: 59400 | G22: 59400 | J22: 0 | K22: -59400 | L22: 0 | M22: 0
B23: 9501119442, 9501168399 | C23: Procurement Services Phase 1 | D23: Mansi | E23: 507357 | G23: 507357 | J23: 0 | K23: -507357 | L23: 0 | M23: 0
B24: 9501296090 | C24: Build 20 Servers in ESXi Servers in Microsoft exchange | D24: Mansi | E24: 14668 | G24: 14668 | J24: 0 | K24: -14668 | L24: 0 | M24: 0
B25: 9501303360 | C25: Project Aegis – Network Vulnerability Management | D25: Mansi | E25: 53016 | G25: 53016 | J25: 0 | K25: -53016 | L25: 0 | M25: 0
A26: Paul Johnson | B26: 9500969299 | C26: iERP: HummingBird SOW - phase 4 2025 | D26: Jaspal Singh | E26: 0 | G26: 0 | J26: 0 | K26: 0 | L26: 1 | M26: 0
A27: Sasidhar V Mullangi | B27: PO Pending | C27: BI: Network Analytics Support 2nd half 2026 | D27: Jaspal Singh | E27: 83283.75 | G27: 83283.75 | J27: 0 | K27: -83283.75 | L27: 0 | M27: 0
C28: BI: External supply Master Data + Cyber Semester 2 2026 | D28: Jaspal Singh | E28: 29859 | G28: 29859 | J28: 0 | K28: -29859 | L28: 0 | M28: 0
C29: BI: T5-T6 - Strategic Digital Enablement (MS) Semester 2 2026 | D29: Jaspal Singh | E29: 50510.25 | G29: 50510.25 | J29: 0 | K29: -50510.25 | L29: 0 | M29: 0
C30: BI: ES Ops Portfolio Lifecycle Semester 2 2026 | D30: Jaspal Singh | E30: 71627 | G30: 71627 | J30: 0 | K30: -71627 | L30: 0 | M30: 0
C31: BI: CMO Integration Semester 2 2026 | D31: Jaspal Singh | E31: 57833.25 | G31: 57833.25 | J31: 0 | K31: -57833.25 | L31: 0 | M31: 0
C32: Supply Planning SIQ BAU Semester 2 | D32: Jaspal Singh | E32: 114700 | G32: 114700 | J32: 0 | K32: -114700 | L32: 0 | M32: 0
C33: Dalian Legacy Trackwise Data ingestion to PGS UDH | D33: Jaspal Singh | E33: 17907.5 | G33: 17907.5 | J33: 0 | K33: -17907.5 | L33: 0 | M33: 0
C34: KZO and Puurs SharePoint data to be ingested in PGS UDH | D34: Jaspal Singh | E34: 13893.5 | G34: 13893.5 | J34: 0 | K34: -13893.5 | L34: 0 | M34: 0
C35: SAIGE - Write Off Agentic AI Solution Phase II | D35: Jaspal Singh | E35: 79987.1 | G35: 79987.1 | J35: 0 | K35: -79987.1 | L35: 0 | M35: 0
C36: NWA BAU Support Semester 2 2026 | D36: Jaspal Singh | E36: 27225 | G36: 27225 | J36: 0 | K36: -27225 | L36: 0 | M36: 0
B37: 9501151669 | C37: BI: SAIGE - AI Summarization agent (Network Analytics) | D37: Jaspal Singh | E37: 68473.75 | G37: 68473.75 | J37: 0 | K37: -68473.75 | L37: 0 | M37: 0
B38: 9501287353 | C38: VMP project Snowflake IIC Developer | D38: Jaspal Singh | E38: 7532.14 | G38: 7532.14 | J38: 0 | K38: -7532.14 | L38: 0 | M38: 0
A39: Bharat Bangera | B39: 9501184708 | C39: BI:GMIS UDH Integration Enhancements and support 2026 | D39: Jaspal Singh | E39: 32936.87 | G39: 32936.87 | J39: 0 | K39: -32936.87 | L39: 0 | M39: 0
B40: 9501192891 | C40: BI: Network analytics Scrum Master Semester 1 2026 | D40: Jaspal Singh | E40: 0 | G40: 0 | J40: 0 | K40: 0 | L40: 1 | M40: 0
...

Sheet IBM POs AP07
A1: PO# | B1: Old POs | C1: PO Name | D1: PO Owner | E1: Cost Center | F1: WBS | G1: Date Requested | H1: Comments | I1: Pfizer Owner | J1: IBM Owner | K1: Forecast Provided | L1: Forecast Provided T&M | M1: Forecast Provided FP | N1: Column1 | O1: Column2
A2: 8503164851 | C2: BI: Plant Migration to SAP: Rocky Mount & McPherson | D2: Farra, Sharon | F2: CE-BTS21076-02-10 | G2: 44682 | H2: BI | K2: =IF((L2=M2),"Not Forecasted","Forecasted") -> Not Forecasted | L2: =IF(ISNUMBER(VLOOKUP(A2,'T&M Details'!D:D,1,0)),"Forecasted","Not Forecasted") -> Not Forecasted | M2: =IF(ISNUMBER(VLOOKUP(B2,'Fixed Price Details'!D:D,1,0)),"Forecasted","Not Forecasted") -> Not Forecasted
A3: 8503222612 | C3: 2022 Serialization OpEx | D3: Beltz, Brandon | E3: 2329531 | F3: IT-PBT0113-OG-US-00 | G3: 44682 | H3: CLOSED ON PFIZER SIDE | I3: Robyn | K3: =IF((L3=M3),"Not Forecasted","Forecasted") -> Not Forecasted | L3: =IF(ISNUMBER(VLOOKUP(A3,'T&M Details'!D:D,1,0)),"Forecasted","Not Forecasted") -> Not Forecasted | M3: =IF(ISNUMBER(VLOOKUP(IBM_PO5[[#This Row],[PO'#]],'Fixed Price Details'!D:D,1,0)),"Forecasted","Not Forecasted") -> Not Forecasted
A4: 8503225962 | C4: IO Solutions Support 2022 | D4: Thomas, Immanual | E4: 2320521 | G4: 44682 | K4: =IF((L4=M4),"Not Forecasted","Forecasted") -> Not Forecasted | L4: =IF(ISNUMBER(VLOOKUP(A4,'T&M Details'!D:D,1,0)),"Forecasted","Not Forecasted") -> Not Forecasted | M4: =IF(ISNUMBER(VLOOKUP(IBM_PO5[[#This Row],[PO'#]],'Fixed Price Details'!D:D,1,0)),"Forecasted","Not Forecasted") -> Not Forecasted
A5: 8503225983 | C5: 2022 IO Solutions Resources for COVID | D5: Thomas, Immanual | F5: CE-BTS21065-02-10-10 | G5: 44682 | K5: =IF((L5=M5),"Not Forecasted","Forecasted") -> Not Forecasted | L5: =IF(ISNUMBER(VLOOKUP(A5,'T&M Details'!D:D,1,0)),"Forecasted","Not Forecasted") -> Not Forecasted | M5: =IF(ISNUMBER(VLOOKUP(IBM_PO5[[#This Row],[PO'#]],'Fixed Price Details'!D:D,1,0)),"Forecasted","Not Forecasted") -> Not Forecasted
A6: 8503228623 | C6: IO CPA 2022 | D6: Thomas, Immanual | F6: CE-BTS21004-02-10 | G6: 44682 | K6: =IF((L6=M6),"Not Forecasted","Forecasted") -> Not Forecasted | L6: =IF(ISNUMBER(VLOOKUP(A6,'T&M Details'!D:D,1,0)),"Forecasted","Not Forecasted") -> Not Forecasted | M6: =IF(ISNUMBER(VLOOKUP(IBM_PO5[[#This Row],[PO'#]],'Fixed Price Details'!D:D,1,0)),"Forecasted","Not Forecasted") -> Not Forecasted
A7: 8503238076 | C7: Rocky Mount McPherson SAP Deployment | D7: Jajodia, Amit | F7: CE-BTS21076-02-10 | G7: 44682 | K7: =IF((L7=M7),"Not Forecasted","Forecasted") -> Not Forecasted | L7: =IF(ISNUMBER(VLOOKUP(A7,'T&M Details'!D:D,1,0)),"Forecasted","Not Forecasted") -> Not Forecasted | M7: =IF(ISNUMBER(VLOOKUP(IBM_PO5[[#This Row],[PO'#]],'Fixed Price Details'!D:D,1,0)),"Forecasted","Not Forecasted") -> Not Forecasted
A8: 8503238189 | C8: ERP LOG CPA 2022 | D8: Aitha, Hari | F8: CE-BTS22009-02-10 | G8: 44682 | H8: CLOSED ON PFIZER SIDE | I8: KINJAL | K8: =IF((L8=M8),"Not Forecasted","Forecasted") -> Not Forecasted | L8: =IF(ISNUMBER(VLOOKUP(A8,'T&M Details'!D:D,1,0)),"Forecasted","Not Forecasted") -> Not Forecasted | M8: =IF(ISNUMBER(VLOOKUP(IBM_PO5[[#This Row],[PO'#]],'Fixed Price Details'!D:D,1,0)),"Forecasted","Not Forecasted") -> Not Forecasted
A9: 8503250261 | C9: 2022 SSCS Planning Continuous Improvement Project Mgt – Scrum Master | D9: White, Glenn | E9: 2351818 | G9: 44682 | H9: CLOSED ON PFIZER SIDE | I9: Michael | K9: =IF((L9=M9),"Not Forecasted","Forecasted") -> Not Forecasted | L9: =IF(ISNUMBER(VLOOKUP(A9,'T&M Details'!D:D,1,0)),"Forecasted","Not Forecasted") -> Not Forecasted | M9: =IF(ISNUMBER(VLOOKUP(IBM_PO5[[#This Row],[PO'#]],'Fixed Price Details'!D:D,1,0)),"Forecasted","Not Forecasted") -> Not Forecasted
A10: 8503250440 | C10: 2022 SSCS Planning Continuous Improvement | D10: White, Glenn | F10: CE-BTS22015-02-10 | G10: 44682 | H10: CLOSED ON PFIZER SIDE | I10: Michael | K10: =IF((L10=M10),"Not Forecasted","Forecasted") -> Not Forecasted | L10: =IF(ISNUMBER(VLOOKUP(A10,'T&M Details'!D:D,1,0)),"Forecasted","Not Forecasted") -> Not Forecasted | M10: =IF(ISNUMBER(VLOOKUP(IBM_PO5[[#This Row],[PO'#]],'Fixed Price Details'!D:D,1,0)),"Forecasted","Not Forecasted") -> Not Forecasted
A11: 8503253085 | C11: IBM SAP SUPPORT SERVICES: TEST AUTOMATIO | D11: Meadows, Leslie | E11: 2321403 | G11: 44682 | K11: =IF((L11=M11),"Not Forecasted","Forecasted") -> Not Forecasted | L11: =IF(ISNUMBER(VLOOKUP(A11,'T&M Details'!D:D,1,0)),"Forecasted","Not Forecasted") -> Not Forecasted | M11: =IF(ISNUMBER(VLOOKUP(IBM_PO5[[#This Row],[PO'#]],'Fixed Price Details'!D:D,1,0)),"Forecasted","Not Forecasted") -> Not Forecasted
A12: 8503257031 | C12: SAP Security Services 2022 | D12: Patel, Nikunj | F12: CE-BTS21064-02-10 | G12: 44682 | H12: CLOSED ON PFIZER SIDE | I12: Robyn | K12: =IF((L12=M12),"Not Forecasted","Forecasted") -> Not Forecasted | L12: =IF(ISNUMBER(VLOOKUP(A12,'T&M Details'!D:D,1,0)),"Forecasted","Not Forecasted") -> Not Forecasted | M12: =IF(ISNUMBER(VLOOKUP(IBM_PO5[[#This Row],[PO'#]],'Fixed Price Details'!D:D,1,0)),"Forecasted","Not Forecasted") -> Not Forecasted
A13: 9500010089 | C13: New Product Launch – Project Manager | D13: Vadassery, Laly | E13: 2351818 | F13: CE-BTS21059-02-EX | G13: 44682 | H13: Checking on status | I13: Robyn | K13: =IF((L13=M13),"Not Forecasted","Forecasted") -> Not Forecasted | L13: =IF(ISNUMBER(VLOOKUP(A13,'T&M Details'!D:D,1,0)),"Forecasted","Not Forecasted") -> Not Forecasted | M13: =IF(ISNUMBER(VLOOKUP(IBM_PO5[[#This Row],[PO'#]],'Fixed Price Details'!D:D,1,0)),"Forecasted","Not Forecasted") -> Not Forecasted
K14: =IF((L14=M14),"Not Forecasted","Forecasted") -> Not Forecasted | L14: =IF(ISNUMBER(VLOOKUP(A14,'T&M Details'!D:D,1,0)),"Forecasted","Not Forecasted") -> Not Forecasted | M14: =IF(ISNUMBER(VLOOKUP(IBM_PO5[[#This Row],[PO'#]],'Fixed Price Details'!D:D,1,0)),"Forecasted","Not Forecasted") -> Not Forecasted
A15: 9500011134 | C15: iERP Continuous Improvement and Support | D15: Pozath, Vasudevan | E15: 2329622 | F15: IT-FBT0504-OG-US-00 | G15: 44682 | H15: BI | K15: =IF((L15=M15),"Not Forecasted","Forecasted") -> Not Forecasted | L15: =IF(ISNUMBER(VLOOKUP(A15,'T&M Details'!D:D,1,0)),"Forecasted","Not Forecasted") -> Not Forecasted | M15: =IF(ISNUMBER(VLOOKUP(IBM_PO5[[#This Row],[PO'#]],'Fixed Price Details'!D:D,1,0)),"Forecasted","Not Forecasted") -> Not Forecasted
A16: 9500012274 | C16: PacOne UDH Datamining project PCR 01 | D16: Sasidhar V Mullangi | G16: 44682 | H16: BI | K16: =IF((L16=M16),"Not Forecasted","Forecasted") -> Not Forecasted | L16: =IF(ISNUMBER(VLOOKUP(A16,'T&M Details'!D:D,1,0)),"Forecasted","Not Forecasted") -> Not Forecasted | M16: =IF(ISNUMBER(VLOOKUP(IBM_PO5[[#This Row],[PO'#]],'Fixed Price Details'!D:D,1,0)),"Forecasted","Not Forecasted") -> Not Forecasted
A17: 9500019463 | B17: 8503143717 | C17: Serialization Solution Migration - Capital | D17: Beltz, Brandon | E17: 2320487 | G17: 44682 | H17: Finished; closure pending | I17: Robyn | K17: =IF((L17=M17),"Not Forecasted","Forecasted") -> Not Forecasted | L17: =IF(ISNUMBER(VLOOKUP(A17,'T&M Details'!D:D,1,0)),"Forecasted","Not Forecasted") -> Not Forecasted | M17: =IF(ISNUMBER(VLOOKUP(IBM_PO5[[#This Row],[PO'#]],'Fixed Price Details'!D:D,1,0)),"Forecasted","Not Forecasted") -> Not Forecasted
A18: 9500019648 | B18: 8503138178 | C18: Serialization Solution Migration - CCA | D18: Beltz, Brandon | E18: 2320487 | G18: 44682 | H18: Finished; closure pending | I18: Robyn | K18: =IF((L18=M18),"Not Forecasted","Forecasted") -> Not Forecasted | L18: =IF(ISNUMBER(VLOOKUP(A18,'T&M Details'!D:D,1,0)),"Forecasted","Not Forecasted") -> Not Forecasted | M18: =IF(ISNUMBER(VLOOKUP(IBM_PO5[[#This Row],[PO'#]],'Fixed Price Details'!D:D,1,0)),"Forecasted","Not Forecasted") -> Not Forecasted
A19: 9500019683 | B19: 8503142466 | C19: Serialization Solution Migration - Expense | D19: Beltz, Brandon | E19: 2320487 | G19: 44682 | H19: Finished; closure pending | I19: Robyn | K19: =IF((L19=M19),"Not Forecasted","Forecasted") -> Not Forecasted | L19: =IF(ISNUMBER(VLOOKUP(A19,'T&M Details'!D:D,1,0)),"Forecasted","Not Forecasted") -> Not Forecasted | M19: =IF(ISNUMBER(VLOOKUP(IBM_PO5[[#This Row],[PO'#]],'Fixed Price Details'!D:D,1,0)),"Forecasted","Not Forecasted") -> Not Forecasted
A20: 9500025724 | C20: IBM - Project NEO | D20: Davenport, Michael | E20: 2356784 | F20: AD-OFG120001-PG-G7-US | G20: 44682 | H20: EMEA | K20: =IF((L20=M20),"Not Forecasted","Forecasted") -> Not Forecasted | L20: =IF(ISNUMBER(VLOOKUP(A20,'T&M Details'!D:D,1,0)),"Forecasted","Not Forecasted") -> Not Forecasted | M20: =IF(ISNUMBER(VLOOKUP(IBM_PO5[[#This Row],[PO'#]],'Fixed Price Details'!D:D,1,0)),"Forecasted","Not Forecasted") -> Not Forecasted
A21: 9500026505 | C21: 2022 IO Solutions Covid Support | D21: Thomas, Immanual | E21: 2351818 | F21: IT-PBU0445-OT-US-00 | G21: 44682 | K21: =IF((L21=M21),"Not Forecasted","Forecasted") -> Not Forecasted | L21: =IF(ISNUMBER(VLOOKUP(A21,'T&M Details'!D:D,1,0)),"Forecasted","Not Forecasted") -> Not Forecasted | M21: =IF(ISNUMBER(VLOOKUP(IBM_PO5[[#This Row],[PO'#]],'Fixed Price Details'!D:D,1,0)),"Forecasted","Not Forecasted") -> Not Forecasted
A22: 9500026681 | C22: SCC Implementation – Consultants for Pilot Phase | D22: Hoffman, Kerry | F22: CCA22PGS03 | G22: 44682 | K22: =IF((L22=M22),"Not Forecasted","Forecasted") -> Not Forecasted | L22: =IF(ISNUMBER(VLOOKUP(A22,'T&M Details'!D:D,1,0)),"Forecasted","Not Forecasted") -> Not Forecasted | M22: =IF(ISNUMBER(VLOOKUP(IBM_PO5[[#This Row],[PO'#]],'Fixed Price Details'!D:D,1,0)),"Forecasted","Not Forecasted") -> Not Forecasted
A23: 9500026715 | C23: RM and McP ERP Deployment Expense (PM and Training) | D23: Jajodia, Amit | E23: 2351818 | F23: CE-BTS21076-02-EX | G23: 44682 | K23: =IF((L23=M23),"Not Forecasted","Forecasted") -> Not Forecasted | L23: =IF(ISNUMBER(VLOOKUP(A23,'T&M Details'!D:D,1,0)),"Forecasted","Not Forecasted") -> Not Forecasted | M23: =IF(ISNUMBER(VLOOKUP(IBM_PO5[[#This Row],[PO'#]],'Fixed Price Details'!D:D,1,0)),"Forecasted","Not Forecasted") -> Not Forecasted
A24: 9500026716 | B24: 8503263618 | C24: Offshore Resource for CI Work | D24: Musty, Prasad | E24: 2351818 | F24: IT-PBU0427-OT-US-00 | G24: 44682 | H24: CLOSED ON PFIZER SIDE | K24: =IF((L24=M24),"Not Forecasted","Forecasted") -> Not Forecasted | L24: =IF(ISNUMBER(VLOOKUP(A24,'T&M Details'!D:D,1,0)),"Forecasted","Not Forecasted") -> Not Forecasted | M24: =IF(ISNUMBER(VLOOKUP(IBM_PO5[[#This Row],[PO'#]],'Fixed Price Details'!D:D,1,0)),"Forecasted","Not Forecasted") -> Not Forecasted
A25: 9500026762 | B25: 8503263618 | C25: Mfg-Q2-Q4 -2022 Offshore Resource for MKT Work | D25: Musty, Prasad | F25: CE-BTS22037-02-10 | G25: 44682 | H25: CLOSED ON PFIZER SIDE | K25: =IF((L25=M25),"Not Forecasted","Forecasted") -> Not Forecasted | L25: =IF(ISNUMBER(VLOOKUP(A25,'T&M Details'!D:D,1,0)),"Forecasted","Not Forecasted") -> Not Forecasted | M25: =IF(ISNUMBER(VLOOKUP(IBM_PO5[[#This Row],[PO'#]],'Fixed Price Details'!D:D,1,0)),"Forecasted","Not Forecasted") -> Not Forecasted
A26: 9500030844 | C26: Technical Services for APO CI projects | D26: Emani, Phani | G26: 44699 | K26: =IF((L26=M26),"Not Forecasted","Forecasted") -> Not Forecasted | L26: =IF(ISNUMBER(VLOOKUP(A26,'T&M Details'!D:D,1,0)),"Forecasted","Not Forecasted") -> Not Forecasted | M26: =IF(ISNUMBER(VLOOKUP(IBM_PO5[[#This Row],[PO'#]],'Fixed Price Details'!D:D,1,0)),"Forecasted","Not Forecasted") -> Not Forecasted
A27: 9500027186 | B27: 8503261702 | C27: MFG CI QM 2022 | D27: Musty, Prasad | F27: CE-BTS22037-02-10 | G27: 44707 | H27: CLOSED ON PFIZER SIDE | K27: =IF((L27=M27),"Not Forecasted","Forecasted") -> Not Forecasted | L27: =IF(ISNUMBER(VLOOKUP(A27,'T&M Details'!D:D,1,0)),"Forecasted","Not Forecasted") -> Not Forecasted | M27: =IF(ISNUMBER(VLOOKUP(IBM_PO5[[#This Row],[PO'#]],'Fixed Price Details'!D:D,1,0)),"Forecasted","Not Forecasted") -> Not Forecasted
A28: 9500036775 | C28: 2022 SSCS Planning Network Change and Pfizer Connect | D28: White, Glenn | E28: 2340695 | G28: 44707 | H28: CLOSED ON PFIZER SIDE | I28: Michael | K28: =IF((L28=M28),"Not Forecasted","Forecasted") -> Not Forecasted | L28: =IF(ISNUMBER(VLOOKUP(A28,'T&M Details'!D:D,1,0)),"Forecasted","Not Forecasted") -> Not Forecasted | M28: =IF(ISNUMBER(VLOOKUP(IBM_PO5[[#This Row],[PO'#]],'Fixed Price Details'!D:D,1,0)),"Forecasted","Not Forecasted") -> Not Forecasted
A29: 8503272080 | C29: SAP Mobility 2022 | D29: Beltz, Brandon | F29: CE-PPK22001-04-01-04 | G29: 44713 | H29: CLOSED ON PFIZER SIDE | I29: Robyn | K29: =IF((L29=M29),"Not Forecasted","Forecasted") -> Not Forecasted | L29: =IF(ISNUMBER(VLOOKUP(A29,'T&M Details'!D:D,1,0)),"Forecasted","Not Forecasted") -> Not Forecasted | M29: =IF(ISNUMBER(VLOOKUP(IBM_PO5[[#This Row],[PO'#]],'Fixed Price Details'!D:D,1,0)),"Forecasted","Not Forecasted") -> Not Forecasted
A30: 9500028140 | C30: ATTP Project Coordinator | D30: Beltz, Brandon | E30: 2329531 | F30: CE-BTS21064-02-EX | G30: 44713 | H30: CLOSED ON PFIZER SIDE | I30: Robyn | K30: =IF((L30=M30),"Not Forecasted","Forecasted") -> Not Forecasted | L30: =IF(ISNUMBER(VLOOKUP(A30,'T&M Details'!D:D,1,0)),"Forecasted","Not Forecasted") -> Not Forecasted | M30: =IF(ISNUMBER(VLOOKUP(IBM_PO5[[#This Row],[PO'#]],'Fixed Price Details'!D:D,1,0)),"Forecasted","Not Forecasted") -> Not Forecasted
A31: 9500038160 | C31: Serialization ERP Functional SME | D31: Beltz, Brandon | F31: CE-PPK22001-04-01-04 | G31: 44713 | H31: CLOSED ON PFIZER SIDE | I31: Robyn | K31: =IF((L31=M31),"Not Forecasted","Forecasted") -> Not Forecasted | L31: =IF(ISNUMBER(VLOOKUP(A31,'T&M Details'!D:D,1,0)),"Forecasted","Not Forecasted") -> Not Forecasted | M31: =IF(ISNUMBER(VLOOKUP(IBM_PO5[[#This Row],[PO'#]],'Fixed Price Details'!D:D,1,0)),"Forecasted","Not Forecasted") -> Not Forecasted
A32: 9500029415 | B32: 9500024140 | C32: IBM-ERP Logistics COVID EMEA Support | D32: Aitha, Hari | G32: 44718 | H32: CLOSED ON PFIZER SIDE | I32: KINJAL | K32: =IF((L32=M32),"Not Forecasted","Forecasted") -> Not Forecasted | L32: =IF(ISNUMBER(VLOOKUP(A32,'T&M Details'!D:D,1,0)),"Forecasted","Not Forecasted") -> Not Forecasted | M32: =IF(ISNUMBER(VLOOKUP(IBM_PO5[[#This Row],[PO'#]],'Fixed Price Details'!D:D,1,0)),"Forecasted","Not Forecasted") -> Not Forecasted
A33: 9500030646 | C33: IBM - Procurement BOD 2022 [43] | D33: Senth Singaram | F33: CE-BTF17008-02-10 | G33: 44720 | K33: =IF((L33=M33),"Not Forecasted","Forecasted") -> Not Forecasted | L33: =IF(ISNUMBER(VLOOKUP(A33,'T&M Details'!D:D,1,0)),"Forecasted","Not Forecasted") -> Not Forecasted | M33: =IF(ISNUMBER(VLOOKUP(IBM_PO5[[#This Row],[PO'#]],'Fixed Price Details'!D:D,1,0)),"Forecasted","Not Forecasted") -> Not Forecasted
A34: 9500045006 | C34: ERP SAP ATTP Phase 2 Q2 2022 - CCA | D34: Beltz, Brandon | F34: CCA21PGS03 | G34: 44733 | H34: Finished; closure pending | I34: Robyn | K34: =IF((L34=M34),"Not Forecasted","Forecasted") -> Not Forecasted | L34: =IF(ISNUMBER(VLOOKUP(A34,'T&M Details'!D:D,1,0)),"Forecasted","Not Forecasted") -> Not Forecasted | M34: =IF(ISNUMBER(VLOOKUP(IBM_PO5[[#This Row],[PO'#]],'Fixed Price Details'!D:D,1,0)),"Forecasted","Not Forecasted") -> Not Forecasted
A35: 9500046249 | C35: ERP SAP ATTP Phase 2 Q2 2022 - Capital | D35: Beltz, Brandon | F35: CE-BTS21064-02-10 | G35: 44733 | H35: Finished; closure pending | I35: Robyn | K35: =IF((L35=M35),"Not Forecasted","Forecasted") -> Not Forecasted | L35: =IF(ISNUMBER(VLOOKUP(A35,'T&M Details'!D:D,1,0)),"Forecasted","Not Forecasted") -> Not Forecasted | M35: =IF(ISNUMBER(VLOOKUP(IBM_PO5[[#This Row],[PO'#]],'Fixed Price Details'!D:D,1,0)),"Forecasted","Not Forecasted") -> Not Forecasted
A36: 9500049432 | C36: IBM-MFG CI Support | D36: Attarde, Rahul | F36: CE-BTS22056-02-10 | G36: 44749 | H36: CLOSED ON PFIZER SIDE | K36: =IF((L36=M36),"Not Forecasted","Forecasted") -> Not Forecasted | L36: =IF(ISNUMBER(VLOOKUP(A36,'T&M Details'!D:D,1,0)),"Forecasted","Not Forecasted") -> Not Forecasted | M36: =IF(ISNUMBER(VLOOKUP(IBM_PO5[[#This Row],[PO'#]],'Fixed Price Details'!D:D,1,0)),"Forecasted","Not Forecasted") -> Not Forecasted
A37: 9500050997 | C37: MFG MES Extension Q2-Q4 2022 | D37: Attarde, Rahul | F37: CE-BTS22056-02-10 | G37: 44750 | H37: EMEA - CLOSED ON PFIZER SIDE | K37: =IF((L37=M37),"Not Forecasted","Forecasted") -> Not Forecasted | L37: =IF(ISNUMBER(VLOOKUP(A37,'T&M Details'!D:D,1,0)),"Forecasted","Not Forecasted") -> Not Forecasted | M37: =IF(ISNUMBER(VLOOKUP(IBM_PO5[[#This Row],[PO'#]],'Fixed Price Details'!D:D,1,0)),"Forecasted","Not Forecasted") -> Not Forecasted
A38: 9500056096 | C38: BI: iGES 2nd Half 2022 Analytics | D38: Bharat B. | G38: 44755 | H38: BI | K38: =IF((L38=M38),"Not Forecasted","Forecasted") -> Not Forecasted | L38: =IF(ISNUMBER(VLOOKUP(A38,'T&M Details'!D:D,1,0)),"Forecasted","Not Forecasted") -> Not Forecasted | M38: =IF(ISNUMBER(VLOOKUP(IBM_PO5[[#This Row],[PO'#]],'Fixed Price Details'!D:D,1,0)),"Forecasted","Not Forecasted") -> Not Forecasted
A39: 9500055768 | C39: BI MDG TINS Migration | D39: Zavala, Maria | G39: 44760 | H39: CLOSED ON PFIZER SIDE | I39: KINJAL | K39: =IF((L39=M39),"Not Forecasted","Forecasted") -> Not Forecasted | L39: =IF(ISNUMBER(VLOOKUP(A39,'T&M Details'!D:D,1,0)),"Forecasted","Not Forecasted") -> Not Forecasted | M39: =IF(ISNUMBER(VLOOKUP(IBM_PO5[[#This Row],[PO'#]],'Fixed Price Details'!D:D,1,0)),"Forecasted","Not Forecasted") -> Not Forecasted
A40: 9500053915 | C40: Serialization UDH Scrum Master | D40: Prabhakar Kothuru | F40: CE-PPK22001-04-01-04 | G40: 44763 | H40: CLOSED ON PFIZER SIDE | I40: Robyn | K40: =IF((L40=M40),"Not Forecasted","Forecasted") -> Not Forecasted | L40: =IF(ISNUMBER(VLOOKUP(A40,'T&M Details'!D:D,1,0)),"Forecasted","Not Forecasted") -> Not Forecasted | M40: =IF(ISNUMBER(VLOOKUP(IBM_PO5[[#This Row],[PO'#]],'Fixed Price Details'!D:D,1,0)),"Forecasted","Not Forecasted") -> Not Forecasted
...

Sheet T&M Details
A1: Pfizer requested PO | B1: PMA | C1: PO Owner | D1: PO # | E1: Work Code | F1: Project Name | G1: Project Start Date | H1: Project End Date | I1: Resource Talent Id | J1: Resource Name | K1: Bill Rate | L1: Location | M1: Resource Status | N1: Forecast Month Hours | O1: Forecast Fee $ | P1: Forecast Expenses $ | Q1: Forecast Total $ | R1: Actual Month Hours | S1: Acual Fee $ | T1: Actual Expenses $ | U1: Actual Total $ | V1: Monthly Hours Variance | W1: Hours Billed Flag | X1: Forecast Accuracy | Y1: Expense% | Z1: Comments | AA1: Total Forecast Hours 2025 | AB1: Jan 2026 - FFHours | AC1: Feb 2026 - FHours | AD1: March 2026 - FHours | AE1: April 2026 - FHours | AF1: May 2026 - FHours | AG1: June 2026 - FHours | AH1: July 2026 - FHours | AI1: Aug 2026 - FHours | AJ1: Sep 2026 - FHours | AK1: Oct 2026 - FHours | AL1: Nov 2026 - FHours | AM1: Dec 2026 - FHours | AN1: 2026 Forecast total Fee | AO1: Jan 2026 - FFee | AP1: Feb 2026 - FFee | AQ1: March 2026 - FFee | AR1: April 2026 - FFee | AS1: May 2026 - FFee | AT1: June 2026 - FFee | AU1: July 2026 - FFee | AV1: Aug 2026 - FFee | AW1: Sep 2026 - FFee | AX1: Oct 2026 - FFee | AY1: Nov 2026 - FFee | AZ1: Dec 2026 - FFee | BA1: 2026 Total Forecast Expenses | BB1: Jan 2026 - FExpenses | BC1: Feb 2026 - FExpenses | BD1: March 2026 - FExpenses | BE1: April 2026 - FExpenses | BF1: May 2026 - FExpenses | BG1: June 2026 - FExpenses | BH1: July 2026 - FExpenses | BI1: Aug 2026 - FExpenses | BJ1: Sep 2026 - FExpenses | BK1: Oct 2026 - FExpenses | BL1: Nov 2026 - FExpenses | BM1: Dec 2026 - FExpenses | BN1: Forecast Total 2026 | BO1: Jan 2026 - FTotal | BP1: Feb 2026 - FTotal | BQ1: March 2026 - FTotal | BR1: April 2026 - FTotal | BS1: May 2026 - FTotal | BT1: June 2026 - FTotal | BU1: July 2026 - FTotal | BV1: Aug 2026 - FTotal | BW1: Sep 2026 - FTotal | BX1: Oct 2026 - FTotal | BY1: Nov 2026 - FTotal | BZ1: Dec 2026 - FTotal
A2: =IF(ISNUMBER(INDEX('IBM POs AP07'!$A:$A, MATCH(D2,'IBM POs AP07'!$A:$A,0),1)),"Yes","No") -> No | B2: Raju Parkala | C2: David McGettigan | D2: 9500905777/9501153096 | E2: W3F1Z | F2: SAP Application Managed Service - SAP BI Factory | G2: 45717 | H2: 47542 | I2: 005P89 | J2: B MANOHAR | K2: 29 | L2: Offshore | N2: =AH2 -> 0 | O2: =N2*K2 -> 0 | P2: =BF2 -> 0 | Q2: =O2+P2 -> 0 | S2: =R2*K2 -> 0 | T2: 0 | U2: =S2+T2 -> 0 | V2: =Q2-U2 -> 0 | W2: =IF(AND(L2="Offshore",R2>N2),"Red Flag",IF(AND(OR(L2="Onshore",L2="EMEA"),R2>N2),"Red Flag","")) | X2: 1 | Y2: 0 | AA2: =SUM(AB2:AM2) -> 668 | AB2: 162 | AC2: 162 | AD2: 192 | AE2: 152 | AF2: 0 | AG2: 0 | AH2: 0 | AI2: 0 | AJ2: 0 | AK2: 0 | AL2: 0 | AM2: 0 | AN2: =SUM(AO2:AZ2) -> 19372 | AO2: =AB2*$K2 -> 4698 | AP2: =AC2*$K2 -> 4698 | AQ2: =AD2*$K2 -> 5568 | AR2: =AE2*$K2 -> 4408 | AS2: =AF2*$K2 -> 0 | AT2: =AG2*$K2 -> 0 | AU2: =AH2*$K2 -> 0 | AV2: =AI2*$K2 -> 0 | ... AZ2: =AM2*$K2 -> 0 | BA2: =SUM(BB2:BM2) -> 0 | BB2: 0 | BC2: 0 | BD2: 0 | BE2: 0 | BF2: 0 | BG2: 0 | BH2: 0 | BI2: 0 | BJ2: 0 | BK2: 0 | BL2: 0 | BM2: 0 | BN2: =SUM(BO2:BZ2) -> 19372 | BO2: =BB2+AO2 -> 4698 | BP2: =BC2+AP2 -> 4698 | BQ2: =BD2+AQ2 -> 5568 | BR2: =BE2+AR2 -> 4408 | BS2: =BF2+AS2 -> 0 | BT2: =BG2+AT2 -> 0 | BU2: =BH2+AU2 -> 0 | BV2: =BI2+AV2 -> 0 | ... BZ2: =BM2+AZ2 -> 0
A3: =IF(ISNUMBER(INDEX('IBM POs AP07'!$A:$A, MATCH(D3,'IBM POs AP07'!$A:$A,0),1)),"Yes","No") -> No | B3: Raju Parkala | C3: David McGettigan | D3: 9500905777/9501153096 | E3: W3F1Z | F3: SAP Application Managed Service - SAP BI Factory | G3: 45717 | H3: 47542 | I3: 005JV3 | J3: SHRUTI BIRE | K3: 29 | L3: Offshore | N3: =AH3 -> 0 | O3: =N3*K3 -> 0 | P3: =BF3 -> 0 | Q3: =O3+P3 -> 0 | S3: =R3*K3 -> 0 | T3: 0 | U3: =S3+T3 -> 0 | V3: =Q3-U3 -> 0 | W3: =IF(AND(L3="Offshore",R3>N3),"Red Flag",IF(AND(OR(L3="Onshore",L3="EMEA"),R3>N3),"Red Flag","")) | X3: 1 | Y3: 0 | AA3: =SUM(AB3:AM3) -> 624 | AB3: 144 | AC3: 153 | AD3: 192 | AE3: 135 | AF3: 0 | AG3: 0 | AN3: =SUM(AO3:AZ3) -> 18096 | AO3: =AB3*$K3 -> 4176 | AP3: =AC3*$K3 -> 4437 | AQ3: =AD3*$K3 -> 5568 | AR3: =AE3*$K3 -> 3915 | AS3: =AF3*$K3 -> 0 | AT3: =AG3*$K3 -> 0 | AU3: =AH3*$K3 -> 0 | AV3: =AI3*$K3 -> 0 | ... AZ3: =AM3*$K3 -> 0 | BA3: =SUM(BB3:BM3) -> 0 | BB3: 0 | BC3: 0 | BD3: 0 | BE3: 0 | BF3: 0 | BG3: 0 | BH3: 0 | BI3: 0 | BJ3: 0 | BK3: 0 | BL3: 0 | BM3: 0 | BN3: =SUM(BO3:BZ3) -> 18096 | BO3: =BB3+AO3 -> 4176 | BP3: =BC3+AP3 -> 4437 | BQ3: =BD3+AQ3 -> 5568 | BR3: =BE3+AR3 -> 3915 | BS3: =BF3+AS3 -> 0 | BT3: =BG3+AT3 -> 0 | BU3: =BH3+AU3 -> 0 | BV3: =BI3+AV3 -> 0 | ... BZ3: =BM3+AZ3 -> 0
A4: =IF(ISNUMBER(INDEX('IBM POs AP07'!$A:$A, MATCH(D4,'IBM POs AP07'!$A:$A,0),1)),"Yes","No") -> No | B4: Raju Parkala | C4: David McGettigan | D4: 9500905777/9501153096 | E4: W3F1Z | F4: SAP Application Managed Service - SAP BI PCR 02 | G4: 45717 | H4: 47542 | K4: 47.5 | L4: Offshore | N4: =AH4 -> 0 | O4: =N4*K4 -> 0 | P4: =BF4 -> 0 | Q4: =O4+P4 -> 0 | S4: =R4*K4 -> 0 | T4: 0 | U4: =S4+T4 -> 0 | V4: =Q4-U4 -> 0 | W4: =IF(AND(L4="Offshore",R4>N4),"Red Flag",IF(AND(OR(L4="Onshore",L4="EMEA"),R4>N4),"Red Flag","")) | X4: 1 | Y4: 0 | AA4: =SUM(AB4:AM4) -> 16 | AB4: 16 | AN4: =SUM(AO4:AZ4) -> 760 | AO4: =AB4*$K4 -> 760 | AP4: =AC4*$K4 -> 0 | AQ4: =AD4*$K4 -> 0 | AR4: =AE4*$K4 -> 0 | AS4: =AF4*$K4 -> 0 | AT4: =AG4*$K4 -> 0 | AU4: =AH4*$K4 -> 0 | AV4: =AI4*$K4 -> 0 | ... AZ4: =AM4*$K4 -> 0 | BA4: =SUM(BB4:BM4) -> 0 | BB4: 0 | BC4: 0 | BD4: 0 | BE4: 0 | BF4: 0 | BG4: 0 | BH4: 0 | BI4: 0 | BJ4: 0 | BK4: 0 | BL4: 0 | BM4: 0 | BN4: =SUM(BO4:BZ4) -> 760 | BO4: =BB4+AO4 -> 760 | BP4: =BC4+AP4 -> 0 | BQ4: =BD4+AQ4 -> 0 | BR4: =BE4+AR4 -> 0 | BS4: =BF4+AS4 -> 0 | BT4: =BG4+AT4 -> 0 | BU4: =BH4+AU4 -> 0 | BV4: =BI4+AV4 -> 0 | ... BZ4: =BM4+AZ4 -> 0
A5: =IF(ISNUMBER(INDEX('IBM POs AP07'!$A:$A, MATCH(D5,'IBM POs AP07'!$A:$A,0),1)),"Yes","No") -> No | B5: Raju Parkala | C5: David McGettigan | D5: 9500905777/9501153096 | E5: W3F1Z | F5: SAP Application Managed Service - SAP BI PCR 03 | G5: 45717 | H5: 47542 | I5: 00547P | J5: LAKSHMAN VATTURI | K5: 42.5 | L5: Offshore | N5: =AH5 -> 0 | O5: =N5*K5 -> 0 | P5: =BF5 -> 0 | Q5: =O5+P5 -> 0 | S5: =R5*K5 -> 0 | T5: 0 | U5: =S5+T5 -> 0 | V5: =Q5-U5 -> 0 | W5: =IF(AND(L5="Offshore",R5>N5),"Red Flag",IF(AND(OR(L5="Onshore",L5="EMEA"),R5>N5),"Red Flag","")) | X5: 1 | Y5: 0 | AA5: =SUM(AB5:AM5) -> 693 | AB5: 162 | AC5: 162 | AD5: 207 | AE5: 162 | AF5: 0 | AG5: 0 | AH5: 0 | AI5: 0 | AJ5: 0 | AK5: 0 | AL5: 0 | AM5: 0 | AN5: =SUM(AO5:AZ5) -> 29452.5 | AO5: =AB5*$K5 -> 6885 | AP5: =AC5*$K5 -> 6885 | AQ5: =AD5*$K5 -> 8797.5 | AR5: =AE5*$K5 -> 6885 | AS5: =AF5*$K5 -> 0 | AT5: =AG5*$K5 -> 0 | AU5: =AH5*$K5 -> 0 | AV5: =AI5*$K5 -> 0 | ... AZ5: =AM5*$K5 -> 0 | BA5: =SUM(BB5:BM5) -> 0 | BB5: 0 | BC5: 0 | BD5: 0 | BE5: 0 | BF5: 0 | BG5: 0 | BH5: 0 | BI5: 0 | BJ5: 0 | BK5: 0 | BL5: 0 | BM5: 0 | BN5: =SUM(BO5:BZ5) -> 29452.5 | BO5: =BB5+AO5 -> 6885 | BP5: =BC5+AP5 -> 6885 | BQ5: =BD5+AQ5 -> 8797.5 | BR5: =BE5+AR5 -> 6885 | BS5: =BF5+AS5 -> 0 | BT5: =BG5+AT5 -> 0 | BU5: =BH5+AU5 -> 0 | BV5: =BI5+AV5 -> 0 | ... BZ5: =BM5+AZ5 -> 0
A6: =IF(ISNUMBER(INDEX('IBM POs AP07'!$A:$A, MATCH(D6,'IBM POs AP07'!$A:$A,0),1)),"Yes","No") -> No | B6: Raju Parkala | C6: Jerome Roberton | D6: Pending Po | E6: YAMVJB | F6: SAP AMS BW Enhancement Requests | G6: 46153 | H6: 46234 | J6: HarshaTej Jadi | K6: 47.5 | N6: =AH6 -> 180 | O6: =N6*K6 -> 8550 | P6: =BF6 -> 0 | Q6: =O6+P6 -> 8550 | S6: =R6*K6 -> 0 | T6: 0 | U6: =S6+T6 -> 0 | V6: =Q6-U6 -> 8550 | W6: =IF(AND(L6="Offshore",R6>N6),"Red Flag",IF(AND(OR(L6="Onshore",L6="EMEA"),R6>N6),"Red Flag","")) | X6: 1 | Y6: 0 | AA6: =SUM(AB6:AM6) -> 504 | AF6: 90 | AG6: 216 | AH6: 180 | AI6: 18 | AN6: =SUM(AO6:AZ6) -> 23940 | AO6: =AB6*$K6 -> 0 | AP6: =AC6*$K6 -> 0 | AQ6: =AD6*$K6 -> 0 | AR6: =AE6*$K6 -> 0 | AS6: =AF6*$K6 -> 4275 | AT6: =AG6*$K6 -> 10260 | AU6: =AH6*$K6 -> 8550 | AV6: =AI6*$K6 -> 855 | ... AZ6: =AM6*$K6 -> 0 | BA6: =SUM(BB6:BM6) -> 0 | BB6: 0 | BC6: 0 | BD6: 0 | BE6: 0 | BF6: 0 | BG6: 0 | BH6: 0 | BI6: 0 | BJ6: 0 | BK6: 0 | BL6: 0 | BM6: 0 | BN6: =SUM(BO6:BZ6) -> 23940 | BO6: =BB6+AO6 -> 0 | BP6: =BC6+AP6 -> 0 | BQ6: =BD6+AQ6 -> 0 | BR6: =BE6+AR6 -> 0 | BS6: =BF6+AS6 -> 4275 | BT6: =BG6+AT6 -> 10260 | BU6: =BH6+AU6 -> 8550 | BV6: =BI6+AV6 -> 855 | ... BZ6: =BM6+AZ6 -> 0
A7: =IF(ISNUMBER(INDEX('IBM POs AP07'!$A:$A, MATCH(D7,'IBM POs AP07'!$A:$A,0),1)),"Yes","No") -> No | B7: Raju Parkala | C7: Ryan Burnside | D7: 9501252591 | E7: YALMFB | F7: SAP SVO CI ES&SC Q2 2026 | G7: 46113 | H7: 46387 | I7: 003GKH | J7: Dheenadhayalan Magendran | K7: 47.5 | L7: Offshore | N7: =AH7 -> 153 | O7: =N7*K7 -> 7267.5 | P7: =BF7 -> 0 | Q7: =O7+P7 -> 7267.5 | S7: =R7*K7 -> 0 | T7: 0 | U7: =S7+T7 -> 0 | V7: =Q7-U7 -> 7267.5 | W7: =IF(AND(L7="Offshore",R7>N7),"Red Flag",IF(AND(OR(L7="Onshore",L7="EMEA"),R7>N7),"Red Flag","")) | X7: 1 | Y7: 0 | AA7: =SUM(AB7:AM7) -> 1188 | AE7: 0 | AF7: 0 | AG7: 0 | AH7: 153 | AI7: 225 | AJ7: 180 | AK7: 180 | AL7: 225 | AM7: 225 | AN7: =SUM(AO7:AZ7) -> 56430 | AO7: =AB7*$K7 -> 0 | AP7: =AC7*$K7 -> 0 | AQ7: =AD7*$K7 -> 0 | AR7: =AE7*$K7 -> 0 | AS7: =AF7*$K7 -> 0 | AT7: =AG7*$K7 -> 0 | AU7: =AH7*$K7 -> 7267.5 | AV7: =AI7*$K7 -> 10687.5 | ... AZ7: =AM7*$K7 -> 10687.5 | BA7: =SUM(BB7:BM7) -> 0 | BB7: 0 | BC7: 0 | BD7: 0 | BE7: 0 | BF7: 0 | BG7: 0 | BH7: 0 | BI7: 0 | BJ7: 0 | BK7: 0 | BL7: 0 | BM7: 0 | BN7: =SUM(BO7:BZ7) -> 56430 | BO7: =BB7+AO7 -> 0 | BP7: =BC7+AP7 -> 0 | BQ7: =BD7+AQ7 -> 0 | BR7: =BE7+AR7 -> 0 | BS7: =BF7+AS7 -> 0 | BT7: =BG7+AT7 -> 0 | BU7: =BH7+AU7 -> 7267.5 | BV7: =BI7+AV7 -> 10687.5 | ... BZ7: =BM7+AZ7 -> 10687.5
A8: =IF(ISNUMBER(INDEX('IBM POs AP07'!$A:$A, MATCH(D8,'IBM POs AP07'!$A:$A,0),1)),"Yes","No") -> No | B8: Raju Parkala | C8: Ryan Burnside | D8: 9501252591 | E8: YALMFB | F8: SAP SVO CI ES&SC Q2 2026 | G8: 46113 | H8: 46387 | I8: 224422 | J8: Mirajgaonkar, Sanjay | K8: 61.75 | L8: Offshore | N8: =AH8 -> 0 | O8: =N8*K8 -> 0 | P8: =BF8 -> 0 | Q8: =O8+P8 -> 0 | S8: =R8*K8 -> 0 | T8: 0 | U8: =S8+T8 -> 0 | V8: =Q8-U8 -> 0 | W8: =IF(AND(L8="Offshore",R8>N8),"Red Flag",IF(AND(OR(L8="Onshore",L8="EMEA"),R8>N8),"Red Flag","")) | X8: 1 | Y8: 0 | AA8: =SUM(AB8:AM8) -> 0 | AE8: 0 | AF8: 0 | AG8: 0 | AH8: 0 | AI8: 0 | AJ8: 0 | AK8: 0 | AL8: 0 | AM8: 0 | AN8: =SUM(AO8:AZ8) -> 0 | AO8: =AB8*$K8 -> 0 | AP8: =AC8*$K8 -> 0 | AQ8: =AD8*$K8 -> 0 | AR8: =AE8*$K8 -> 0 | AS8: =AF8*$K8 -> 0 | AT8: =AG8*$K8 -> 0 | AU8: =AH8*$K8 -> 0 | AV8: =AI8*$K8 -> 0 | ... AZ8: =AM8*$K8 -> 0 | BA8: =SUM(BB8:BM8) -> 0 | BB8: 0 | BC8: 0 | BD8: 0 | BE8: 0 | BF8: 0 | BG8: 0 | BH8: 0 | BI8: 0 | BJ8: 0 | BK8: 0 | BL8: 0 | BM8: 0 | BN8: =SUM(BO8:BZ8) -> 0 | BO8: =BB8+AO8 -> 0 | BP8: =BC8+AP8 -> 0 | BQ8: =BD8+AQ8 -> 0 | BR8: =BE8+AR8 -> 0 | BS8: =BF8+AS8 -> 0 | BT8: =BG8+AT8 -> 0 | BU8: =BH8+AU8 -> 0 | BV8: =BI8+AV8 -> 0 | ... BZ8: =BM8+AZ8 -> 0
A9: =IF(ISNUMBER(INDEX('IBM POs AP07'!$A:$A, MATCH(D9,'IBM POs AP07'!$A:$A,0),1)),"Yes","No") -> No | B9: Raju Parkala | C9: Ryan Burnside | D9: 9501252591 | E9: YALMFB | F9: SAP SVO CI ES&SC Q2 2026 | G9: 46113 | H9: 46387 | I9: 0345C7 | J9: SANTOSH BAKALKAR | K9: 61.75 | L9: Offshore | N9: =AH9 -> 171 | O9: =N9*K9 -> 10559.25 | P9: =BF9 -> 0 | Q9: =O9+P9 -> 10559.25 | S9: =R9*K9 -> 0 | T9: 0 | U9: =S9+T9 -> 0 | V9: =Q9-U9 -> 10559.25 | W9: =IF(AND(L9="Offshore",R9>N9),"Red Flag",IF(AND(OR(L9="Onshore",L9="EMEA"),R9>N9),"Red Flag","")) | X9: 1 | Y9: 0 | AA9: =SUM(AB9:AM9) -> 1524 | AE9: 0 | AF9: 120 | AG9: 198 | AH9: 171 | AI9: 225 | AJ9: 180 | AK9: 180 | AL9: 225 | AM9: 225 | AN9: =SUM(AO9:AZ9) -> 94107 | AO9: =AB9*$K9 -> 0 | AP9: =AC9*$K9 -> 0 | AQ9: =AD9*$K9 -> 0 | AR9: =AE9*$K9 -> 0 | AS9: =AF9*$K9 -> 7410 | AT9: =AG9*$K9 -> 12226.5 | AU9: =AH9*$K9 -> 10559.25 | AV9: =AI9*$K9 -> 13893.75 | ... AZ9: =AM9*$K9 -> 13893.75 | BA9: =SUM(BB9:BM9) -> 0 | BB9: 0 | BC9: 0 | BD9: 0 | BE9: 0 | BF9: 0 | BG9: 0 | BH9: 0 | BI9: 0 | BJ9: 0 | BK9: 0 | BL9: 0 | BM9: 0 | BN9: =SUM(BO9:BZ9) -> 94107 | BO9: =BB9+AO9 -> 0 | BP9: =BC9+AP9 -> 0 | BQ9: =BD9+AQ9 -> 0 | BR9: =BE9+AR9 -> 0 | BS9: =BF9+AS9 -> 7410 | BT9: =BG9+AT9 -> 12226.5 | BU9: =BH9+AU9 -> 10559.25 | BV9: =BI9+AV9 -> 13893.75 | ... BZ9: =BM9+AZ9 -> 13893.75
A10: =IF(ISNUMBER(INDEX('IBM POs AP07'!$A:$A, MATCH(D10,'IBM POs AP07'!$A:$A,0),1)),"Yes","No") -> No | B10: Raju Parkala | C10: Ryan Burnside | D10: 9501252591 | E10: YALMFB | F10: SAP SVO CI ES&SC Q2 2026 | G10: 46113 | H10: 46387 | I10: 34937 | J10: VASUDEVA THIMMAIAH | K10: 180 | L10: Onshore | N10: =AH10 -> 0 | O10: =N10*K10 -> 0 | P10: =BF10 -> 0 | Q10: =O10+P10 -> 0 | S10: =R10*K10 -> 0 | T10: 0 | U10: =S10+T10 -> 0 | V10: =Q10-U10 -> 0 | W10: =IF(AND(L10="Offshore",R10>N10),"Red Flag",IF(AND(OR(L10="Onshore",L10="EMEA"),R10>N10),"Red Flag","")) | X10: 1 | Y10: 0 | AA10: =SUM(AB10:AM10) -> 176 | AE10: 144 | AF10: 32 | AN10: =SUM(AO10:AZ10) -> 31680 | AO10: =AB10*$K10 -> 0 | AP10: =AC10*$K10 -> 0 | AQ10: =AD10*$K10 -> 0 | AR10: =AE10*$K10 -> 25920 | AS10: =AF10*$K10 -> 5760 | AT10: =AG10*$K10 -> 0 | AU10: =AH10*$K10 -> 0 | AV10: =AI10*$K10 -> 0 | ... AZ10: =AM10*$K10 -> 0 | BA10: =SUM(BB10:BM10) -> 0 | BB10: 0 | BC10: 0 | BD10: 0 | BE10: 0 | BF10: 0 | BG10: 0 | BH10: 0 | BI10: 0 | BJ10: 0 | BK10: 0 | BL10: 0 | BM10: 0 | BN10: =SUM(BO10:BZ10) -> 31680 | BO10: =BB10+AO10 -> 0 | BP10: =BC10+AP10 -> 0 | BQ10: =BD10+AQ10 -> 0 | BR10: =BE10+AR10 -> 25920 | BS10: =BF10+AS10 -> 5760 | BT10: =BG10+AT10 -> 0 | BU10: =BH10+AU10 -> 0 | BV10: =BI10+AV10 -> 0 | ... BZ10: =BM10+AZ10 -> 0
A11: =IF(ISNUMBER(INDEX('IBM POs AP07'!$A:$A, MATCH(D11,'IBM POs AP07'!$A:$A,0),1)),"Yes","No") -> No | B11: Raju Parkala | C11: Ryan Burnside | D11: 9501252591 | E11: YALMFB | F11: SAP SVO CI ES&SC Q2 2026 | G11: 46113 | H11: 46387 | I11: 01906H | J11: RAHUL SHIROTE | K11: 47.5 | N11: =AH11 -> 153 | O11: =N11*K11 -> 7267.5 | P11: =BF11 -> 0 | Q11: =O11+P11 -> 7267.5 | S11: =R11*K11 -> 0 | T11: 0 | U11: =S11+T11 -> 0 | V11: =Q11-U11 -> 7267.5 | W11: =IF(AND(L11="Offshore",R11>N11),"Red Flag",IF(AND(OR(L11="Onshore",L11="EMEA"),R11>N11),"Red Flag","")) | X11: 1 | Y11: 0 | AA11: =SUM(AB11:AM11) -> 1188 | AH11: 153 | AI11: 225 | AJ11: 180 | AK11: 180 | AL11: 225 | AM11: 225 | AN11: =SUM(AO11:AZ11) -> 56430 | AO11: =AB11*$K11 -> 0 | AP11: =AC11*$K11 -> 0 | AQ11: =AD11*$K11 -> 0 | AR11: =AE11*$K11 -> 0 | AS11: =AF11*$K11 -> 0 | AT11: =AG11*$K11 -> 0 | AU11: =AH11*$K11 -> 7267.5 | AV11: =AI11*$K11 -> 10687.5 | ... AZ11: =AM11*$K11 -> 10687.5 | BA11: =SUM(BB11:BM11) -> 0 | BB11: 0 | BC11: 0 | BD11: 0 | BE11: 0 | BF11: 0 | BG11: 0 | BH11: 0 | BI11: 0 | BJ11: 0 | BK11: 0 | BL11: 0 | BM11: 0 | BN11: =SUM(BO11:BZ11) -> 56430 | BO11: =BB11+AO11 -> 0 | BP11: =BC11+AP11 -> 0 | BQ11: =BD11+AQ11 -> 0 | BR11: =BE11+AR11 -> 0 | BS11: =BF11+AS11 -> 0 | BT11: =BG11+AT11 -> 0 | BU11: =BH11+AU11 -> 7267.5 | BV11: =BI11+AV11 -> 10687.5 | ... BZ11: =BM11+AZ11 -> 10687.5
A12: =IF(ISNUMBER(INDEX('IBM POs AP07'!$A:$A, MATCH(D12,'IBM POs AP07'!$A:$A,0),1)),"Yes","No") -> No | B12: Raju Parkala | C12: Ryan Burnside | D12: 9501252591 | E12: YALMFB | F12: SAP SVO CI ES&SC Q2 2026 | G12: 46113 | H12: 46387 | I12: 0042UQ | J12: RADHA GANDRAKOTA | K12: 47.5 | N12: =AH12 -> 0 | O12: =N12*K12 -> 0 | P12: =BF12 -> 0 | Q12: =O12+P12 -> 0 | S12: =R12*K12 -> 0 | T12: 0 | U12: =S12+T12 -> 0 | V12: =Q12-U12 -> 0 | W12: =IF(AND(L12="Offshore",R12>N12),"Red Flag",IF(AND(OR(L12="Onshore",L12="EMEA"),R12>N12),"Red Flag","")) | X12: 1 | Y12: 0 | AA12: =SUM(AB12:AM12) -> 585 | AK12: 135 | AL12: 225 | AM12: 225 | AN12: =SUM(AO12:AZ12) -> 27787.5 | AO12: =AB12*$K12 -> 0 | AP12: =AC12*$K12 -> 0 | AQ12: =AD12*$K12 -> 0 | AR12: =AE12*$K12 -> 0 | AS12: =AF12*$K12 -> 0 | AT12: =AG12*$K12 -> 0 | AU12: =AH12*$K12 -> 0 | AV12: =AI12*$K12 -> 0 | ... AZ12: =AM12*$K12 -> 10687.5 | BA12: =SUM(BB12:BM12) -> 0 | BB12: 0 | BC12: 0 | BD12: 0 | BE12: 0 | BF12: 0 | BG12: 0 | BH12: 0 | BI12: 0 | BJ12: 0 | BK12: 0 | BL12: 0 | BM12: 0 | BN12: =SUM(BO12:BZ12) -> 27787.5 | BO12: =BB12+AO12 -> 0 | BP12: =BC12+AP12 -> 0 | BQ12: =BD12+AQ12 -> 0 | BR12: =BE12+AR12 -> 0 | BS12: =BF12+AS12 -> 0 | BT12: =BG12+AT12 -> 0 | BU12: =BH12+AU12 -> 0 | BV12: =BI12+AV12 -> 0 | ... BZ12: =BM12+AZ12 -> 10687.5
A13: =IF(ISNUMBER(INDEX('IBM POs AP07'!$A:$A, MATCH(D13,'IBM POs AP07'!$A:$A,0),1)),"Yes","No") -> No | B13: Raju Parkala | C13: Amit Jajodia | D13: 9501273936 | E13: YAMWDB | F13: SAP SVO BRM QM Q2 2026 | G13: 46113 | H13: 46203 | I13: 005XI6 | J13: AMOL SHITOLE | K13: 87 | N13: =AH13 -> 18 | O13: =N13*K13 -> 1566 | P13: =BF13 -> 0 | Q13: =O13+P13 -> 1566 | S13: =R13*K13 -> 0 | T13: 0 | U13: =S13+T13 -> 0 | V13: =Q13-U13 -> 1566 | W13: =IF(AND(L13="Offshore",R13>N13),"Red Flag",IF(AND(OR(L13="Onshore",L13="EMEA"),R13>N13),"Red Flag","")) | X13: 1 | Y13: 0 | AA13: =SUM(AB13:AM13) -> 387 | AE13: 0 | AF13: 171 | AG13: 198 | AH13: 18 | AN13: =SUM(AO13:AZ13) -> 33669 | AO13: =AB13*$K13 -> 0 | AP13: =AC13*$K13 -> 0 | AQ13: =AD13*$K13 -> 0 | AR13: =AE13*$K13 -> 0 | AS13: =AF13*$K13 -> 14877 | AT13: =AG13*$K13 -> 17226 | AU13: =AH13*$K13 -> 1566 | AV13: =AI13*$K13 -> 0 | ... AZ13: =AM13*$K13 -> 0 | BA13: =SUM(BB13:BM13) -> 0 | BB13: 0 | BC13: 0 | BD13: 0 | BE13: 0 | BF13: 0 | BG13: 0 | BH13: 0 | BI13: 0 | BJ13: 0 | BK13: 0 | BL13: 0 | BM13: 0 | BN13: =SUM(BO13:BZ13) -> 33669 | BO13: =BB13+AO13 -> 0 | BP13: =BC13+AP13 -> 0 | BQ13: =BD13+AQ13 -> 0 | BR13: =BE13+AR13 -> 0 | BS13: =BF13+AS13 -> 14877 | BT13: =BG13+AT13 -> 17226 | BU13: =BH13+AU13 -> 1566 | BV13: =BI13+AV13 -> 0 | ... BZ13: =BM13+AZ13 -> 0
A14: =IF(ISNUMBER(INDEX('IBM POs AP07'!$A:$A, MATCH(D14,'IBM POs AP07'!$A:$A,0),1)),"Yes","No") -> No | B14: Raju Parkala | C14: Amit Jajodia | D14: 9501274181 | E14: YAMWDB | F14: SAP SVO BRM QM Q2 2026 | G14: 46113 | H14: 46203 | I14: SV5XWG | J14: RAM KUMAR VEPURI | K14: 47.5 | N14: =AH14 -> 18 | O14: =N14*K14 -> 855 | P14: =BF14 -> 0 | Q14: =O14+P14 -> 855 | S14: =R14*K14 -> 0 | T14: 0 | U14: =S14+T14 -> 0 | V14: =Q14-U14 -> 855 | W14: =IF(AND(L14="Offshore",R14>N14),"Red Flag",IF(AND(OR(L14="Onshore",L14="EMEA"),R14>N14),"Red Flag","")) | X14: 1 | Y14: 0 | AA14: =SUM(AB14:AM14) -> 234 | AG14: 216 | AH14: 18 | AN14: =SUM(AO14:AZ14) -> 11115 | AO14: =AB14*$K14 -> 0 | AP14: =AC14*$K14 -> 0 | AQ14: =AD14*$K14 -> 0 | AR14: =AE14*$K14 -> 0 | AS14: =AF14*$K14 -> 0 | AT14: =AG14*$K14 -> 10260 | AU14: =AH14*$K14 -> 855 | AV14: =AI14*$K14 -> 0 | ... AZ14: =AM14*$K14 -> 0 | BA14: =SUM(BB14:BM14) -> 0 | BB14: 0 | BC14: 0 | BD14: 0 | BE14: 0 | BF14: 0 | BG14: 0 | BH14: 0 | BI14: 0 | BJ14: 0 | BK14: 0 | BL14: 0 | BM14: 0 | BN14: =SUM(BO14:BZ14) -> 11115 | BO14: =BB14+AO14 -> 0 | BP14: =BC14+AP14 -> 0 | BQ14: =BD14+AQ14 -> 0 | BR14: =BE14+AR14 -> 0 | BS14: =BF14+AS14 -> 0 | BT14: =BG14+AT14 -> 10260 | BU14: =BH14+AU14 -> 855 | BV14: =BI14+AV14 -> 0 | ... BZ14: =BM14+AZ14 -> 0
A15: =IF(ISNUMBER(INDEX('IBM POs AP07'!$A:$A, MATCH(D15,'IBM POs AP07'!$A:$A,0),1)),"Yes","No") -> No | B15: Raju Parkala | C15: Amit Jajodia | D15: 9501182078 | E15: YAMT9B | F15: SAP SVO QM gLIMS Q2 2026 | G15: 46113 | H15: 46203 | I15: 003XA1 | J15: Palas Sinhamahapatra | K15: 61.75 | N15: =AH15 -> 18 | O15: =N15*K15 -> 1111.5 | P15: =BF15 -> 0 | Q15: =O15+P15 -> 1111.5 | S15: =R15*K15 -> 0 | T15: 0 | U15: =S15+T15 -> 0 | V15: =Q15-U15 -> 1111.5 | W15: =IF(AND(L15="Offshore",R15>N15),"Red Flag",IF(AND(OR(L15="Onshore",L15="EMEA"),R15>N15),"Red Flag","")) | X15: 1 | Y15: 0 | AA15: =SUM(AB15:AM15) -> 558 | AE15: 135 | AF15: 180 | AG15: 225 | AH15: 18 | AN15: =SUM(AO15:AZ15) -> 34456.5 | AO15: =AB15*$K15 -> 0 | AP15: =AC15*$K15 -> 0 | AQ15: =AD15*$K15 -> 0 | AR15: =AE15*$K15 -> 8336.25 | AS15: =AF15*$K15 -> 11115 | AT15: =AG15*$K15 -> 13893.75 | AU15: =AH15*$K15 -> 1111.5 | AV15: =AI15*$K15 -> 0 | ... AZ15: =AM15*$K15 -> 0 | BA15: =SUM(BB15:BM15) -> 0 | BB15: 0 | BC15: 0 | BD15: 0 | BE15: 0 | BF15: 0 | BG15: 0 | BH15: 0 | BI15: 0 | BJ15: 0 | BK15: 0 | BL15: 0 | BM15: 0 | BN15: =SUM(BO15:BZ15) -> 34456.5 | BO15: =BB15+AO15 -> 0 | BP15: =BC15+AP15 -> 0 | BQ15: =BD15+AQ15 -> 0 | BR15: =BE15+AR15 -> 8336.25 | BS15: =BF15+AS15 -> 11115 | BT15: =BG15+AT15 -> 13893.75 | BU15: =BH15+AU15 -> 1111.5 | BV15: =BI15+AV15 -> 0 | ... BZ15: =BM15+AZ15 -> 0
A16: =IF(ISNUMBER(INDEX('IBM POs AP07'!$A:$A, MATCH(D16,'IBM POs AP07'!$A:$A,0),1)),"Yes","No") -> No | B16: Raju Parkala | C16: Amit Jajodia | D16: 9501276525 | E16: YANDLB | F16: AP SVO QM Projects and Support 2026 ` | G16: 46113 | H16: 46203 | I16: 005PC1 | J16: NIMBALKAR NAGANATH DADASO | K16: 31.5 | N16: =AH16 -> 18 | O16: =N16*K16 -> 567 | P16: =BF16 -> 0 | Q16: =O16+P16 -> 567 | S16: =R16*K16 -> 0 | T16: 0 | U16: =S16+T16 -> 0 | V16: =Q16-U16 -> 567 | W16: =IF(AND(L16="Offshore",R16>N16),"Red Flag",IF(AND(OR(L16="Onshore",L16="EMEA"),R16>N16),"Red Flag","")) | X16: 1 | Y16: 0 | AA16: =SUM(AB16:AM16) -> 423 | AF16: 180 | AG16: 225 | AH16: 18 | AN16: =SUM(AO16:AZ16) -> 13324.5 | AO16: =AB16*$K16 -> 0 | AP16: =AC16*$K16 -> 0 | AQ16: =AD16*$K16 -> 0 | AR16: =AE16*$K16 -> 0 | AS16: =AF16*$K16 -> 5670 | AT16: =AG16*$K16 -> 7087.5 | AU16: =AH16*$K16 -> 567 | AV16: =AI16*$K16 -> 0 | ... AZ16: =AM16*$K16 -> 0 | BA16: =SUM(BB16:BM16) -> 0 | BB16: 0 | BC16: 0 | BD16: 0 | BE16: 0 | BF16: 0 | BG16: 0 | BH16: 0 | BI16: 0 | BJ16: 0 | BK16: 0 | BL16: 0 | BM16: 0 | BN16: =SUM(BO16:BZ16) -> 13324.5 | BO16: =BB16+AO16 -> 0 | BP16: =BC16+AP16 -> 0 | BQ16: =BD16+AQ16 -> 0 | BR16: =BE16+AR16 -> 0 | BS16: =BF16+AS16 -> 5670 | BT16: =BG16+AT16 -> 7087.5 | BU16: =BH16+AU16 -> 567 | BV16: =BI16+AV16 -> 0 | ... BZ16: =BM16+AZ16 -> 0
A17: =IF(ISNUMBER(INDEX('IBM POs AP07'!$A:$A, MATCH(D17,'IBM POs AP07'!$A:$A,0),1)),"Yes","No") -> No | B17: Raju Parkala | C17: Amit Jajodia | D17: 9501276525 | E17: YANDLB | F17: AP SVO QM Projects and Support 2026 ` | G17: 46113 | H17: 46203 | I17: 006AX4 | J17: LAKSHMI KOPPULA | K17: 31.5 | N17: =AH17 -> 18 | O17: =N17*K17 -> 567 | P17: =BF17 -> 0 | Q17: =O17+P17 -> 567 | S17: =R17*K17 -> 0 | T17: 0 | U17: =S17+T17 -> 0 | V17: =Q17-U17 -> 567 | W17: =IF(AND(L17="Offshore",R17>N17),"Red Flag",IF(AND(OR(L17="Onshore",L17="EMEA"),R17>N17),"Red Flag","")) | X17: 1 | Y17: 0 | AA17: =SUM(AB17:AM17) -> 342 | AF17: 99 | AG17: 225 | AH17: 18 | AN17: =SUM(AO17:AZ17) -> 10773 | AO17: =AB17*$K17 -> 0 | AP17: =AC17*$K17 -> 0 | AQ17: =AD17*$K17 -> 0 | AR17: =AE17*$K17 -> 0 | AS17: =AF17*$K17 -> 3118.5 | AT17: =AG17*$K17 -> 7087.5 | AU17: =AH17*$K17 -> 567 | AV17: =AI17*$K17 -> 0 | ... AZ17: =AM17*$K17 -> 0 | BA17: =SUM(BB17:BM17) -> 0 | BB17: 0 | BC17: 0 | BD17: 0 | BE17: 0 | BF17: 0 | BG17: 0 | BH17: 0 | BI17: 0 | BJ17: 0 | BK17: 0 | BL17: 0 | BM17: 0 | BN17: =SUM(BO17:BZ17) -> 10773 | BO17: =BB17+AO17 -> 0 | BP17: =BC17+AP17 -> 0 | BQ17: =BD17+AQ17 -> 0 | BR17: =BE17+AR17 -> 0 | BS17: =BF17+AS17 -> 3118.5 | BT17: =BG17+AT17 -> 7087.5 | BU17: =BH17+AU17 -> 567 | BV17: =BI17+AV17 -> 0 | ... BZ17: =BM17+AZ17 -> 0
A18: =IF(ISNUMBER(INDEX('IBM POs AP07'!$A:$A, MATCH(D18,'IBM POs AP07'!$A:$A,0),1)),"Yes","No") -> No | B18: Raju Parkala | C18: Amit Jajodia | D18: 9501285236 | E18: YANDLB | F18: AP SVO QM Projects and Support 2026 ` | G18: 46113 | H18: 46203 | I18: SVKYIE | J18: MIRIYALA GANESH | K18: 31.5 | N18: =AH18 -> 18 | O18: =N18*K18 -> 567 | P18: =BF18 -> 0 | Q18: =O18+P18 -> 567 | S18: =R18*K18 -> 0 | T18: 0 | U18: =S18+T18 -> 0 | V18: =Q18-U18 -> 567 | W18: =IF(AND(L18="Offshore",R18>N18),"Red Flag",IF(AND(OR(L18="Onshore",L18="EMEA"),R18>N18),"Red Flag","")) | X18: 1 | Y18: 0 | AA18: =SUM(AB18:AM18) -> 423 | AF18: 180 | AG18: 225 | AH18: 18 | AN18: =SUM(AO18:AZ18) -> 13324.5 | AO18: =AB18*$K18 -> 0 | AP18: =AC18*$K18 -> 0 | AQ18: =AD18*$K18 -> 0 | AR18: =AE18*$K18 -> 0 | AS18: =AF18*$K18 -> 5670 | AT18: =AG18*$K18 -> 7087.5 | AU18: =AH18*$K18 -> 567 | AV18: =AI18*$K18 -> 0 | ... AZ18: =AM18*$K18 -> 0 | BA18: =SUM(BB18:BM18) -> 0 | BB18: 0 | BC18: 0 | BD18: 0 | BE18: 0 | BF18: 0 | BG18: 0 | BH18: 0 | BI18: 0 | BJ18: 0 | BK18: 0 | BL18: 0 | BM18: 0 | BN18: =SUM(BO18:BZ18) -> 13324.5 | BO18: =BB18+AO18 -> 0 | BP18: =BC18+AP18 -> 0 | BQ18: =BD18+AQ18 -> 0 | BR18: =BE18+AR18 -> 0 | BS18: =BF18+AS18 -> 5670 | BT18: =BG18+AT18 -> 7087.5 | BU18: =BH18+AU18 -> 567 | BV18: =BI18+AV18 -> 0 | ... BZ18: =BM18+AZ18 -> 0
A19: =IF(ISNUMBER(INDEX('IBM POs AP07'!$A:$A, MATCH(D19,'IBM POs AP07'!$A:$A,0),1)),"Yes","No") -> No | B19: Raju Parkala | C19: Amit Jajodia | D19: 9501292172 | E19: YANDLB | F19: AP SVO QM Projects and Support 2026 ` | G19: 46113 | H19: 46203 | J19: Kiran Gaddam / TBD33 / SAP QM Projects and Support | K19: 47.5 | N19: =AH19 -> 18 | O19: =N19*K19 -> 855 | P19: =BF19 -> 0 | Q19: =O19+P19 -> 855 | S19: =R19*K19 -> 0 | T19: 0 | U19: =S19+T19 -> 0 | V19: =Q19-U19 -> 855 | W19: =IF(AND(L19="Offshore",R19>N19),"Red Flag",IF(AND(OR(L19="Onshore",L19="EMEA"),R19>N19),"Red Flag","")) | X19: 1 | Y19: 0 | AA19: =SUM(AB19:AM19) -> 558 | AE19: 135 | AF19: 180 | AG19: 225 | AH19: 18 | AN19: =SUM(AO19:AZ19) -> 26505 | AO19: =AB19*$K19 -> 0 | AP19: =AC19*$K19 -> 0 | AQ19: =AD19*$K19 -> 0 | AR19: =AE19*$K19 -> 6412.5 | AS19: =AF19*$K19 -> 8550 | AT19: =AG19*$K19 -> 10687.5 | AU19: =AH19*$K19 -> 855 | AV19: =AI19*$K19 -> 0 | ... AZ19: =AM19*$K19 -> 0 | BA19: =SUM(BB19:BM19) -> 0 | BB19: 0 | BC19: 0 | BD19: 0 | BE19: 0 | BF19: 0 | BG19: 0 | BH19: 0 | BI19: 0 | BJ19: 0 | BK19: 0 | BL19: 0 | BM19: 0 | BN19: =SUM(BO19:BZ19) -> 26505 | BO19: =BB19+AO19 -> 0 | BP19: =BC19+AP19 -> 0 | BQ19: =BD19+AQ19 -> 0 | BR19: =BE19+AR19 -> 6412.5 | BS19: =BF19+AS19 -> 8550 | BT19: =BG19+AT19 -> 10687.5 | BU19: =BH19+AU19 -> 855 | BV19: =BI19+AV19 -> 0 | ... BZ19: =BM19+AZ19 -> 0
A20: =IF(ISNUMBER(INDEX('IBM POs AP07'!$A:$A, MATCH(D20,'IBM POs AP07'!$A:$A,0),1)),"Yes","No") -> No | B20: Raju Parkala | C20: Amit Jajodia | D20: 9501276524 | E20: YANDLB | F20: AP SVO QM Projects and Support 2026 ` | G20: 46113 | H20: 46203 | I20: 005OH4 | J20: BHAVANA DWARAKAMAI | K20: 47.5 | N20: =AH20 -> 18 | O20: =N20*K20 -> 855 | P20: =BF20 -> 0 | Q20: =O20+P20 -> 855 | S20: =R20*K20 -> 0 | T20: 0 | U20: =S20+T20 -> 0 | V20: =Q20-U20 -> 855 | W20: =IF(AND(L20="Offshore",R20>N20),"Red Flag",IF(AND(OR(L20="Onshore",L20="EMEA"),R20>N20),"Red Flag","")) | X20: 1 | Y20: 0 | AA20: =SUM(AB20:AM20) -> 423 | AF20: 180 | AG20: 225 | AH20: 18 | AN20: =SUM(AO20:AZ20) -> 20092.5 | AO20: =AB20*$K20 -> 0 | AP20: =AC20*$K20 -> 0 | AQ20: =AD20*$K20 -> 0 | AR20: =AE20*$K20 -> 0 | AS20: =AF20*$K20 -> 8550 | AT20: =AG20*$K20 -> 10687.5 | AU20: =AH20*$K20 -> 855 | AV20: =AI20*$K20 -> 0 | ... AZ20: =AM20*$K20 -> 0 | BA20: =SUM(BB20:BM20) -> 0 | BB20: 0 | BC20: 0 | BD20: 0 | BE20: 0 | BF20: 0 | BG20: 0 | BH20: 0 | BI20: 0 | BJ20: 0 | BK20: 0 | BL20: 0 | BM20: 0 | BN20: =SUM(BO20:BZ20) -> 20092.5 | BO20: =BB20+AO20 -> 0 | BP20: =BC20+AP20 -> 0 | BQ20: =BD20+AQ20 -> 0 | BR20: =BE20+AR20 -> 0 | BS20: =BF20+AS20 -> 8550 | BT20: =BG20+AT20 -> 10687.5 | BU20: =BH20+AU20 -> 855 | BV20: =BI20+AV20 -> 0 | ... BZ20: =BM20+AZ20 -> 0
A21: =IF(ISNUMBER(INDEX('IBM POs AP07'!$A:$A, MATCH(D21,'IBM POs AP07'!$A:$A,0),1)),"Yes","No") -> No | B21: Raju Parkala | C21: Sachin Vaidya | D21: 9501173555 | E21: YALQJB | F21: SAP SVO CI Commercial 2026 | G21: 46113 | H21: 46387 | I21: 06048A | J21: DILIP PAMMINA | K21: 180 | L21: Onshore | N21: =AH21 -> 152 | O21: =N21*K21 -> 27360 | P21: =BF21 -> 0 | Q21: =O21+P21 -> 27360 | S21: =R21*K21 -> 0 | T21: 0 | U21: =S21+T21 -> 0 | V21: =Q21-U21 -> 27360 | W21: =IF(AND(L21="Offshore",R21>N21),"Red Flag",IF(AND(OR(L21="Onshore",L21="EMEA"),R21>N21),"Red Flag","")) | X21: 1 | Y21: 0 | AA21: =SUM(AB21:AM21) -> 1493 | AE21: 144 | AF21: 160 | AG21: 184 | AH21: 152 | AI21: 192 | AJ21: 152 | AK21: 152 | AL21: 184 | AM21: 173 | AN21: =SUM(AO21:AZ21) -> 268740 | AO21: =AB21*$K21 -> 0 | AP21: =AC21*$K21 -> 0 | AQ21: =AD21*$K21 -> 0 | AR21: =AE21*$K21 -> 25920 | AS21: =AF21*$K21 -> 28800 | AT21: =AG21*$K21 -> 33120 | AU21: =AH21*$K21 -> 27360 | AV21: =AI21*$K21 -> 34560 | ... AZ21: =AM21*$K21 -> 31140 | BA21: =SUM(BB21:BM21) -> 0 | BB21: 0 | BC21: 0 | BD21: 0 | BE21: 0 | BF21: 0 | BG21: 0 | BH21: 0 | BI21: 0 | BJ21: 0 | BK21: 0 | BL21: 0 | BM21: 0 | BN21: =SUM(BO21:BZ21) -> 268740 | BO21: =BB21+AO21 -> 0 | BP21: =BC21+AP21 -> 0 | BQ21: =BD21+AQ21 -> 0 | BR21: =BE21+AR21 -> 25920 | BS21: =BF21+AS21 -> 28800 | BT21: =BG21+AT21 -> 33120 | BU21: =BH21+AU21 -> 27360 | BV21: =BI21+AV21 -> 34560 | ... BZ21: =BM21+AZ21 -> 31140
A22: =IF(ISNUMBER(INDEX('IBM POs AP07'!$A:$A, MATCH(D22,'IBM POs AP07'!$A:$A,0),1)),"Yes","No") -> No | B22: Raju Parkala | C22: Sachin Vaidya | D22: 9501173555 | E22: YALQJB | F22: SAP SVO CI Commercial 2026 | G22: 46113 | H22: 46387 | I22: 06788J | J22: DEVENDRA DESHPANDE | K22: 180 | L22: Onshore | N22: =AH22 -> 60 | O22: =N22*K22 -> 10800 | P22: =BF22 -> 0 | Q22: =O22+P22 -> 10800 | S22: =R22*K22 -> 0 | T22: 0 | U22: =S22+T22 -> 0 | V22: =Q22-U22 -> 10800 | W22: =IF(AND(L22="Offshore",R22>N22),"Red Flag",IF(AND(OR(L22="Onshore",L22="EMEA"),R22>N22),"Red Flag","")) | X22: 1 | Y22: 0 | AA22: =SUM(AB22:AM22) -> 544 | AE22: 40 | AF22: 64 | AG22: 80 | AH22: 60 | AI22: 60 | AJ22: 60 | AK22: 60 | AL22: 60 | AM22: 60 | AN22: =SUM(AO22:AZ22) -> 97920 | AO22: =AB22*$K22 -> 0 | AP22: =AC22*$K22 -> 0 | AQ22: =AD22*$K22 -> 0 | AR22: =AE22*$K22 -> 7200 | AS22: =AF22*$K22 -> 11520 | AT22: =AG22*$K22 -> 14400 | AU22: =AH22*$K22 -> 10800 | AV22: =AI22*$K22 -> 10800 | ... AZ22: =AM22*$K22 -> 10800 | BA22: =SUM(BB22:BM22) -> 0 | BB22: 0 | BC22: 0 | BD22: 0 | BE22: 0 | BF22: 0 | BG22: 0 | BH22: 0 | BI22: 0 | BJ22: 0 | BK22: 0 | BL22: 0 | BM22: 0 | BN22: =SUM(BO22:BZ22) -> 97920 | BO22: =BB22+AO22 -> 0 | BP22: =BC22+AP22 -> 0 | BQ22: =BD22+AQ22 -> 0 | BR22: =BE22+AR22 -> 7200 | BS22: =BF22+AS22 -> 11520 | BT22: =BG22+AT22 -> 14400 | BU22: =BH22+AU22 -> 10800 | BV22: =BI22+AV22 -> 10800 | ... BZ22: =BM22+AZ22 -> 10800
