Workbook

Sheet Interim2 Pvt
A2: Expense Category | B2: Match | C2: Project Code* | D2: Grouping | E2: Sum of 2026 LE0 | F2: Sum of LE2 Final Submission | G2: Sum of LE3 Final Submission | H2: Sum of LE4 Final Submission | I2: Sum of AP01 | J2: Sum of AP02 | K2: Sum of AP03 | L2: Sum of AP04 | M2: Sum of AP05 | N2: Sum of AP06 | O2: Sum of AP07 | P2: Sum of AP08 | Q2: Sum of AP09 | R2: Sum of AP10 | S2: Sum of AP11 | T2: Sum of AP12 | U2: Sum of 2026 Working Total | V2: Sum of 2026 Working Total to Budget/LE
A3: Expense Category | B3: Match | C3: Project Code* | D3: Grouping | E3: Sum of 2026 LE0 | F3: Sum of LE2 Final Submission | G3: Sum of LE3 Final Submission | H3: Sum of LE4 Final Submission | I3: Sum of AP01 | J3: Sum of AP02 | K3: Sum of AP03 | L3: Sum of AP04 | M3: Sum of AP05 | N3: Sum of AP06 | O3: Sum of AP07 | P3: Sum of AP08 | Q3: Sum of AP09 | R3: Sum of AP10 | S3: Sum of AP11 | T3: Sum of AP12 | U3: Sum of 2026 Working Total | V3: Sum of 2026 Working Total to Budget/LE
A4: COMPENSATION | B4: Dougherty, Chris_COMPENSATION_CompBenefits001 | C4: CompBenefits001 | D4: None | E4: 3920122.7 | F4: 0 | L4: 0 | M4: 0 | N4: 0 | O4: 0 | P4: 0 | Q4: 0 | R4: 0 | S4: 0 | T4: 0 | U4: 0 | V4: 0
B5: Dougherty, Chris_COMPENSATION_CompBonus001 | C5: CompBonus001 | D5: None | E5: 1729258.8 | F5: 0 | L5: 0 | M5: 0 | N5: 0 | O5: 0 | P5: 0 | Q5: 0 | R5: 0 | S5: 0 | T5: 0 | U5: 0 | V5: 0
B6: Dougherty, Chris_COMPENSATION_CompSalary001 | C6: CompSalary001 | D6: None | E6: 9831851.3 | F6: 15406113 | I6: 1402914.4 | J6: 1397677.6 | K6: 1375284.8 | L6: 1433399.5 | M6: 1510809.2 | N6: 1433646.3 | O6: 1208851.7 | P6: 1221091.4 | Q6: 1194419.3 | R6: 1239489.3 | S6: 1239489.3 | T6: 1254635.1 | U6: 15911708 | V6: 505595.34
B7: Ganesan, Srinivasan_COMPENSATION_CompBenefits001 | C7: CompBenefits001 | D7: None | E7: 0 | F7: 0 | L7: 0 | M7: 0 | N7: 0 | O7: 0 | P7: 0 | Q7: 0 | R7: 0 | S7: 0 | T7: 0 | U7: 0 | V7: 0
B8: Ganesan, Srinivasan_COMPENSATION_CompBonus001 | C8: CompBonus001 | D8: None | E8: 0 | F8: 0 | L8: 0 | M8: 0 | N8: 0 | O8: 0 | P8: 0 | Q8: 0 | R8: 0 | S8: 0 | T8: 0 | U8: 0 | V8: 0
B9: Ganesan, Srinivasan_COMPENSATION_CompSalary001 | C9: CompSalary001 | D9: None | E9: 0 | F9: 0 | N9: 11264.34 | O9: 0 | P9: 0 | Q9: 0 | R9: 0 | S9: 0 | T9: 0 | U9: 11264.34 | V9: 11264.34
B10: Hase, Raj_COMPENSATION_CompSalary001 | C10: CompSalary001 | D10: None | E10: 16484281 | F10: 21816550 | I10: 1733431 | J10: 2659121.5 | K10: 1591278.2 | L10: 2358182.7 | M10: 54442.76 | N10: 1905380.4 | O10: 1785306.7 | P10: 1781851.7 | Q10: 1807055.8 | R10: 1862531.5 | S10: 1871210 | T10: 1871210 | U10: 21281002 | V10: -535547.68
B11: Jajodia, Amit_COMPENSATION_CompBenefits001 | C11: CompBenefits001 | D11: None | E11: 0 | F11: 0 | L11: 0 | M11: 0 | N11: 0 | O11: 0 | P11: 0 | Q11: 0 | R11: 0 | S11: 0 | T11: 0 | U11: 0 | V11: 0
B12: Jajodia, Amit_COMPENSATION_CompBonus001 | C12: CompBonus001 | D12: None | E12: 0 | F12: 0 | L12: 0 | M12: 0 | N12: 0 | O12: 0 | P12: 0 | Q12: 0 | R12: 0 | S12: 0 | T12: 0 | U12: 0 | V12: 0
B13: Jajodia, Amit_COMPENSATION_CompSalary001 | C13: CompSalary001 | D13: None | E13: 0 | F13: 0 | N13: 14481.86 | O13: 0 | P13: 0 | Q13: 0 | R13: 0 | S13: 0 | T13: 0 | U13: 14481.86 | V13: 14481.86
B14: Patel, Apurva_COMPENSATION_CompBenefits001 | C14: CompBenefits001 | D14: None | E14: 7282938.3 | F14: 0 | L14: 0 | M14: 0 | N14: 0 | U14: 0 | V14: 0
B15: Patel, Apurva_COMPENSATION_CompBenefitsCar001 | C15: CompBenefitsCar001 | D15: None | E15: 144000 | F15: 108000 | L15: 0 | M15: 0 | N15: 0 | O15: 12000 | P15: 12000 | Q15: 12000 | R15: 12000 | S15: 12000 | T15: 12000 | U15: 72000 | V15: -36000
B16: Patel, Apurva_COMPENSATION_CompBonus001 | C16: CompBonus001 | D16: None | E16: 3070616.4 | F16: 0 | L16: 0 | M16: 0 | N16: 0 | U16: 0 | V16: 0
B17: Patel, Apurva_COMPENSATION_CompSalary001 | C17: CompSalary001 | D17: None | E17: 794938.18 | F17: 806177.42 | I17: 358290.86 | J17: -25689.76 | K17: 41090.67 | L17: 85849.4 | M17: -59378.36 | N17: -23605.23 | O17: 55233.75 | P17: 55233.75 | Q17: 55233.75 | R17: 55233.75 | S17: 55233.75 | T17: 55233.75 | U17: 707960.08 | V17: -98217.34
B18: Patel, Apurva_COMPENSATION_VacancyFactor001 | C18: VacancyFactor001 | D18: Reserve | E18: -472222.21 | F18: -160000 | L18: 0 | M18: 0 | N18: 0 | O18: -20000 | P18: -20000 | Q18: -20000 | R18: -20000 | S18: -20000 | T18: -20000 | U18: -120000 | V18: 40000
B19: Robertson, Jerome_COMPENSATION_CompBenefits001 | C19: CompBenefits001 | D19: None | E19: 763217.95 | F19: 0 | L19: 0 | M19: 0 | N19: 0 | U19: 0 | V19: 0
B20: Robertson, Jerome_COMPENSATION_CompBonus001 | C20: CompBonus001 | D20: None | E20: 355072.04 | F20: 0 | L20: 0 | M20: 0 | N20: 0 | U20: 0 | V20: 0
B21: Robertson, Jerome_COMPENSATION_CompSalary001 | C21: CompSalary001 | D21: None | E21: 2029390.9 | F21: 3060870.8 | I21: 238474.07 | J21: 255306.3 | K21: 190399.43 | L21: 293204.89 | M21: 312206.58 | N21: 165290.4 | O21: 239240.84 | P21: 265188.33 | Q21: 265188.33 | R21: 278462.33 | S21: 278462.33 | T21: 278462.33 | U21: 3059886.2 | V21: -984.69814
A22: COMPENSATION Total | E22: 45933465 | F22: 41037711 | I22: 3733110.3 | J22: 4286415.7 | K22: 3198053.1 | L22: 4170636.5 | M22: 1818080.2 | N22: 3506458.1 | O22: 3280633 | P22: 3315365.2 | Q22: 3313897.1 | R22: 3427716.8 | S22: 3436395.3 | T22: 3451541.1 | U22: 40938303 | V22: -99408.184
A23: CONTRACTORS | B23: Dougherty, Chris_CONTRACTORS_ColleagueSolutions001 | C23: ColleagueSolutions001 | D23: None | E23: 3014.4 | F23: 4510.8 | L23: 0 | M23: 0 | N23: 0 | O23: 101.2 | P23: 101.2 | Q23: 101.2 | R23: 101.2 | S23: 101.2 | T23: 101.2 | U23: 607.2 | V23: -3903.6
B24: Dougherty, Chris_CONTRACTORS_EnhanceChargeout001 | C24: EnhanceChargeout001 | D24: None | E24: -694940 | F24: -708903.73 | I24: 44340 | J24: -102307.86 | K24: -95095.87 | L24: 157664 | M24: -158270 | N24: -154824 | O24: -11640 | P24: -116400 | Q24: -75000 | R24: -75000 | S24: -75000 | T24: -75000 | U24: -736533.73 | V24: -27630
D25: (blank) | L25: 24147 | M25: -46130 | N25: -215360 | U25: -237343 | V25: -237343
B26: Dougherty, Chris_CONTRACTORS_EP&SCharges001 | C26: EP&SCharges001 | D26: EP&S | E26: 0 | F26: 1080 | I26: 360 | J26: 360 | K26: 360 | L26: 0 | M26: 0 | N26: 0 | O26: 0 | P26: 0 | Q26: 0 | R26: 0 | S26: 0 | T26: 0 | U26: 1080 | V26: 0
D27: (blank) | M27: 550 | N27: 0 | U27: 550 | V27: 550
B28: Dougherty, Chris_CONTRACTORS_IT-CTR0044-OG-US-00 | C28: IT-CTR0044-OG-US-00 | D28: None | E28: 551723.04 | F28: 460642 | L28: 0 | M28: 29102.65 | N28: 67355.9 | O28: 58020 | P28: 58020 | Q28: 62525 | R28: 48020 | S28: 42525 | T28: 34020 | U28: 399588.55 | V28: -61053.45
B29: Dougherty, Chris_CONTRACTORS_IT-CTR0067-OG-CR-00 | C29: IT-CTR0067-OG-CR-00 | D29: None | E29: 0 | F29: 214.49 | I29: 215.71 | J29: -1.22 | K29: 0 | L29: 0 | M29: 0 | N29: 0 | O29: 0 | P29: 0 | Q29: 0 | R29: 0 | S29: 0 | T29: 0 | U29: 214.49 | V29: 0
B30: Dougherty, Chris_CONTRACTORS_IT-CTR0093-OG-US-00 | C30: IT-CTR0093-OG-US-00 | D30: 2024 Transfer | E30: 345518.86 | F30: 345670.24 | I30: 35812 | J30: 40109.44 | K30: 50136.8 | L30: 40109.45 | M30: 40109.45 | N30: 29136.78 | O30: 22297 | P30: 19127 | Q30: 19127 | R30: 19127 | S30: 19127 | T30: 19127 | U30: 353345.92 | V30: 7675.68
B31: Dougherty, Chris_CONTRACTORS_IT-CTR0094-OG-US-00 | C31: IT-CTR0094-OG-US-00 | D31: SAP | E31: 216000 | F31: 197423.06 | I31: 14166 | J31: 18835.37 | K31: 16863.69 | L31: 15866.15 | M31: 15866.16 | N31: 19832.69 | O31: 17000 | P31: 17000 | Q31: 17000 | R31: 17000 | S31: 17000 | T31: 17000 | U31: 203430.06 | V31: 6007
B32: Dougherty, Chris_CONTRACTORS_IT-CTR0096-OG-US-00 | C32: IT-CTR0096-OG-US-00 | D32: SAP | E32: 237888 | F32: 236045.4 | I32: 16372 | J32: 18336.62 | K32: 22920.78 | L32: 18336.63 | M32: 18336.63 | N32: 22920.78 | O32: 19824 | P32: 19824 | Q32: 19824 | R32: 19824 | S32: 19824 | T32: 19824 | U32: 236167.44 | V32: 122.04
B33: Dougherty, Chris_CONTRACTORS_IT-CTR0097-OG-US-00 | C33: IT-CTR0097-OG-US-00 | D33: 2024 Transfer | E33: 230004 | F33: 211390.3 | I33: 14973 | J33: 18162.76 | K33: 19567.54 | L33: 16769.23 | M33: 16769.23 | N33: -21713.76 | O33: 17440 | P33: 17440 | Q33: 17440 | R33: 17440 | S33: 17440 | T33: 17440 | U33: 169168 | V33: -42222.3
B34: Dougherty, Chris_CONTRACTORS_IT-CTR0098-OG-US-00 | C34: IT-CTR0098-OG-US-00 | D34: 2024 Transfer | E34: 187200 | F34: 185657.15 | I34: 12857 | J34: 18823.15 | K34: 13577 | L34: 14400 | M34: 17263 | N34: 36956.74 | O34: 15600 | P34: 15600 | Q34: 15600 | R34: 15600 | S34: 15600 | T34: 15600 | U34: 207476.89 | V34: 21819.74
B35: Dougherty, Chris_CONTRACTORS_IT-CTR0099-OG-US-00 | C35: IT-CTR0099-OG-US-00 | D35: 2024 Transfer | E35: 141310.95 | F35: 132735.51 | I35: 9654 | J35: 14825.74 | K35: 12851.77 | L35: 7463.62 | M35: 16343.61 | N35: 13997.28 | O35: 6534 | P35: 6534 | Q35: 6534 | R35: 6534 | S35: 6534 | T35: 6534 | U35: 114340.02 | V35: -18395.49
B36: Dougherty, Chris_CONTRACTORS_IT-CTR0101-OG-US-00 | C36: IT-CTR0101-OG-US-00 | D36: None | E36: 97500 | F36: 90751.67 | I36: 10704.42 | J36: 11988.8 | K36: 9558.45 | L36: 6923.07 | M36: 8819.08 | N36: 6012.11 | O36: 6000 | P36: 6000 | Q36: 6000 | R36: 7500 | S36: 7500 | T36: 7500 | U36: 94505.93 | V36: 3754.26
B37: Dougherty, Chris_CONTRACTORS_IT-CTR0102-OG-US-00 | C37: IT-CTR0102-OG-US-00 | D37: None | E37: 107910 | F37: 99679.13 | I37: 6841 | J37: 9759.2 | K37: 7478.93 | L37: 7661.53 | M37: 9759.54 | N37: 8299.79 | O37: 8300 | P37: 8300 | Q37: 8300 | R37: 8300 | S37: 8300 | T37: 8300 | U37: 99599.99 | V37: -79.14
B38: Dougherty, Chris_CONTRACTORS_IT-CTR0103-OG-US-00 | C38: IT-CTR0103-OG-US-00 | D38: None | E38: 87360 | F38: 83873.7 | I38: 11538 | J38: 8258.77 | K38: 1796.93 | L38: 5175.54 | M38: 10565.53 | N38: 3972.93 | O38: 7000 | P38: 7000 | Q38: 7000 | R38: 7000 | S38: 7000 | T38: 7000 | U38: 83307.7 | V38: -566
B39: Dougherty, Chris_CONTRACTORS_IT-CTR0105-OG-US-00 | C39: IT-CTR0105-OG-US-00 | D39: None | E39: 750 | F39: 0 | L39: 0 | M39: 0 | N39: 0 | U39: 0 | V39: 0
B40: Dougherty, Chris_CONTRACTORS_IT-CTR0130-OG-US-00 | C40: IT-CTR0130-OG-US-00 | D40: None | E40: 357000 | F40: 356999.8 | I40: 24570 | J40: 27517.44 | K40: 34397.36 | L40: 27517.89 | M40: 27517.89 | N40: 34397.36 | O40: 29750 | P40: 29750 | Q40: 37050 | R40: 29750 | S40: 29750 | T40: 29750 | U40: 361717.94 | V40: 4718.14
B41: Dougherty, Chris_CONTRACTORS_IT-CTR0132-OT-US-00 | C41: IT-CTR0132-OT-US-00 | D41: None | E41: 1678341.6 | F41: 1647348.4 | I41: 113142.14 | J41: 160853.86 | K41: 137841.36 | L41: 0 | M41: 274558.24 | N41: 137279.12 | O41: 0 | P41: 274558 | Q41: 137279 | R41: 0 | S41: 274558 | T41: 137279 | U41: 1647348.7 | V41: 0.36
...

Sheet ERP
V2: =V3-AL3 -> 57848.84
U3: =V3-554586-35645 -> 554347.86 | V3: =SUBTOTAL(9,ERP_8[2026 LE0]) -> 1144578.9 | W3: =SUBTOTAL(9,ERP_8[LE2 Final Submission]) -> 1232202.9 | X3: =SUBTOTAL(9,ERP_8[LE3 Final Submission]) -> 0 | Y3: =SUBTOTAL(9,ERP_8[LE4 Final Submission]) -> 0 | Z3: =SUBTOTAL(9,ERP_8[AP01]) -> 124106 | AA3: =SUBTOTAL(9,ERP_8[AP02]) -> 279597 | AB3: =SUBTOTAL(9,ERP_8[AP03]) -> 270738 | AC3: =SUBTOTAL(9,ERP_8[AP04]) -> 224079 | AD3: =SUBTOTAL(9,ERP_8[AP05]) -> -87798 | AE3: =SUBTOTAL(9,ERP_8[AP06]) -> -72135 | AF3: =SUBTOTAL(9,ERP_8[AP07]) -> 239901.02 | AG3: =SUBTOTAL(9,ERP_8[AP08]) -> -47778 | AH3: =SUBTOTAL(9,ERP_8[AP09]) -> 118477 | AI3: =SUBTOTAL(9,ERP_8[AP10]) -> 175123 | AJ3: =SUBTOTAL(9,ERP_8[AP11]) -> -26320 | AK3: =SUBTOTAL(9,ERP_8[AP12]) -> -111260 | AL3: =SUBTOTAL(9,ERP_8[2026 Working Total]) -> 1086730 | AM3: =SUBTOTAL(9,ERP_8[2026 Working Total to Budget/LE]) -> -145472.85 | AN3: =SUBTOTAL(9,ERP_8[Latest AP Snapshot]) -> 16400 | AO3: =SUBTOTAL(9,ERP_8[Latest AP Variance to Snapshot]) -> -88535 | AP3: =SUBTOTAL(9,ERP_8[YTD Act to Bud/LE]) -> 12780.1 | AQ3: =SUBTOTAL(9,ERP_8[Giveback]) -> 0 | AR3: =SUBTOTAL(9,ERP_8[Other Allocation]) -> -145472.85 | AT3: =SUBTOTAL(9,ERP_8[AP01 LE2]) -> 124106 | AU3: =SUBTOTAL(9,ERP_8[AP02 LE2]) -> 279597 | AV3: =SUBTOTAL(9,ERP_8[AP03 LE2]) -> 270738 | AW3: =SUBTOTAL(9,ERP_8[AP04 LE2]) -> 97715 | AX3: =SUBTOTAL(9,ERP_8[AP05 LE2]) -> 81860 | AY3: =SUBTOTAL(9,ERP_8[AP06 LE2]) -> 59831.92 | AZ3: =SUBTOTAL(9,ERP_8[AP07 LE2]) -> 51860 | BA3: =SUBTOTAL(9,ERP_8[AP08 LE2]) -> 51144 | BB3: =SUBTOTAL(9,ERP_8[AP09 LE2]) -> 64076.95 | BC3: =SUBTOTAL(9,ERP_8[AP10 LE2]) -> 47974 | BD3: =SUBTOTAL(9,ERP_8[AP11 LE2]) -> 47974 | BE3: =SUBTOTAL(9,ERP_8[AP12 LE2]) -> 55326 | BF3: =SUBTOTAL(9,ERP_8[2026 LE2 Working Total]) -> 1232202.9 | BG3: =SUBTOTAL(9,ERP_8[2026 AP01]) -> 124106 | BH3: =SUBTOTAL(9,ERP_8[2026 AP02]) -> 279597 | BI3: =SUBTOTAL(9,ERP_8[2026 AP03]) -> 270738 | BJ3: =SUBTOTAL(9,ERP_8[2026 AP04]) -> 116163 | BK3: =SUBTOTAL(9,ERP_8[2026 AP05]) -> 51100 | BL3: =SUBTOTAL(9,ERP_8[2026 AP06]) -> 69791.92 | BM3: =SUBTOTAL(9,ERP_8[2026 AP07]) -> 69563 | BN3: =SUBTOTAL(9,ERP_8[2026 AP08]) -> 68847 | BO3: =SUBTOTAL(9,ERP_8[2026 AP09]) -> 84949.95 | BP3: =SUBTOTAL(9,ERP_8[2026 AP10]) -> 68847 | BQ3: =SUBTOTAL(9,ERP_8[2026 AP11]) -> 68847 | BR3: =SUBTOTAL(9,ERP_8[2026 AP12]) -> 81097 | BS3: =SUBTOTAL(9,ERP_8[2026 LE0 Submission]) -> 1353646.9
O5: Digital Funded Projects | U5: Submissions | V5: Pre LE2 from Planful | Z5: Working Forecast | AP5: Variance & Giveback Analysis | AT5: Prior Submission | BG5: Pre LE2 from Planful
V6: 0223 Extract | W6: 518 | X6: 821 | Y6: 1023 | Z6: Actual | AA6: Actual | AB6: Actual | AC6: Actual | AD6: Actual | AE6: Actual | AF6: Actual | AG6: Forecast | AH6: Forecast | AI6: Forecast | AJ6: Forecast | AK6: Forecast | AN6: AP07 | AP6: YTD Variance | AQ6: (Input) | AR6: (Calculated) | AT6: LE2 | AU6: LE2 | AV6: LE2 | AW6: LE2 | AX6: LE2 | AY6: LE2 | AZ6: LE2 | BA6: LE2 | BB6: LE2 | BC6: LE2 | BD6: LE2 | BE6: LE2 | BF6: LE2 | BG6: 0223 Planful | BH6: 0223 Planful | BI6: 0223 Planful | BJ6: 0223 Planful | BK6: 0223 Planful | BL6: 0223 Planful | BM6: 0223 Planful | BN6: 0223 Planful | BO6: 0223 Planful | BP6: 0223 Planful | BQ6: 0223 Planful | BR6: 0223 Planful | BS6: 0223 Planful
A7: UID | B7: Match | C7: UID2 | D7: NM | E7: NLT | F7: NPOC | G7: CCL3 | H7: LT Member* | I7: LT Member -1* | J7: Point of Contact | K7: Expense Category | L7: Description* | M7: Vendor* | N7: Cost Center* | O7: Project Code* | P7: Prior Year PO | Q7: 2026 Purchase Order | R7: Pullforward | S7: Grouping | T7: 2026 Budget Comment | U7: 2026 Transfers | V7: 2026 LE0 | W7: LE2 Final Submission | X7: LE3 Final Submission | Y7: LE4 Final Submission | Z7: AP01 | AA7: AP02 | AB7: AP03 | AC7: AP04 | AD7: AP05 | AE7: AP06 | AF7: AP07 | AG7: AP08 | AH7: AP09 | AI7: AP10 | AJ7: AP11 | AK7: AP12 | AL7: 2026 Working Total | AM7: 2026 Working Total to Budget/LE | AN7: Latest AP Snapshot | AO7: Latest AP Variance to Snapshot | AP7: YTD Act to Bud/LE | AQ7: Giveback | AR7: Other Allocation | AS7: Giveback Comments | AT7: AP01 LE2 | AU7: AP02 LE2 | AV7: AP03 LE2 | AW7: AP04 LE2 | AX7: AP05 LE2 | AY7: AP06 LE2 | AZ7: AP07 LE2 | BA7: AP08 LE2 | BB7: AP09 LE2 | BC7: AP10 LE2 | BD7: AP11 LE2 | BE7: AP12 LE2 | BF7: 2026 LE2 Working Total | BG7: 2026 AP01 | BH7: 2026 AP02 | BI7: 2026 AP03 | BJ7: 2026 AP04 | BK7: 2026 AP05 | BL7: 2026 AP06 | BM7: 2026 AP07 | BN7: 2026 AP08 | BO7: 2026 AP09 | BP7: 2026 AP10 | BQ7: 2026 AP11 | BR7: 2026 AP12 | BS7: 2026 LE0 Submission
A8: L-ERP-324 | B8: Maguire, Karla_CONTRACTORS_ColleagueSolutions001 | D8: =_xlfn.TEXTJOIN("_",FALSE,E8,ERP_8[[#This Row],[Expense Category]],ERP_8[[#This Row],[Project Code*]]) -> Dougherty, Chris_CONTRACTORS_ColleagueSolutions001 | E8: Dougherty, Chris | G8: ERP | H8: Dougherty, Chris | I8: Maguire, Karla | J8: Maguire, Karla | K8: CONTRACTORS | L8: Colleague Solutions Delivery Chargebacks | O8: ColleagueSolutions001 | P8: CHW - Ok | Q8: N/A | S8: None | T8: KP- Could you confirm who this line was transferred to? | V8: 1214.4 | W8: 910.8 | AD8: 0 | AE8: 0 | AG8: 101.2 | AH8: 101.2 | AI8: 101.2 | AJ8: 101.2 | AK8: 101.2 | AL8: =SUM(Z8:AK8) -> 506 | AM8: =ERP_8[[#This Row],[2026 Working Total]]-ERP_8[[#This Row],[LE2 Final Submission]] -> -404.8 | AN8: 0 | AO8: =$AE8 - $AN8 -> 0 | AP8: =SUM(ERP_8[[#This Row],[AP01]:[AP07]])-SUM(ERP_8[[#This Row],[AP01 LE2]:[AP07 LE2]]) -> -404.8 | AR8: =ERP_8[[#This Row],[2026 Working Total to Budget/LE]]-ERP_8[[#This Row],[Giveback]] -> -404.8 | AW8: 101.2 | AX8: 101.2 | AY8: 101.2 | AZ8: 101.2 | BA8: 101.2 | BB8: 101.2 | BC8: 101.2 | BD8: 101.2 | BE8: 101.2 | BF8: 910.8 | BJ8: 101.2 | BK8: 101.2 | BL8: 101.2 | BM8: 101.2 | BN8: 101.2 | BO8: 101.2 | BP8: 101.2 | BQ8: 101.2 | BR8: 101.2 | BS8: 910.8
A9: L-ERP-369 | B9: McCormick, Pete_CONTRACTORS_ColleagueSolutions001 | D9: =_xlfn.TEXTJOIN("_",FALSE,E9,ERP_8[[#This Row],[Expense Category]],ERP_8[[#This Row],[Project Code*]]) -> Dougherty, Chris_CONTRACTORS_ColleagueSolutions001 | E9: Dougherty, Chris | G9: ERP | H9: Dougherty, Chris | I9: McCormick, Pete | J9: Maguire, Karla | K9: CONTRACTORS | L9: Colleague Solutions Delivery Chargebacks | O9: ColleagueSolutions001 | P9: CHW - Ok | Q9: N/A | S9: None | V9: 1800 | W9: 3600 | AD9: 0 | AE9: 0 | AG9: 0 | AH9: 0 | AI9: 1800 | AJ9: 0 | AK9: 0 | AL9: =SUM(Z9:AK9) -> 1800 | AM9: =ERP_8[[#This Row],[2026 Working Total]]-ERP_8[[#This Row],[LE2 Final Submission]] -> -1800 | AN9: 0 | AO9: =$AE9 - $AN9 -> 0 | AP9: =SUM(ERP_8[[#This Row],[AP01]:[AP07]])-SUM(ERP_8[[#This Row],[AP01 LE2]:[AP07 LE2]]) -> -3600 | AR9: =ERP_8[[#This Row],[2026 Working Total to Budget/LE]]-ERP_8[[#This Row],[Giveback]] -> -1800 | AW9: 1800 | AX9: 0 | AY9: 1800 | AZ9: 0 | BA9: 0 | BB9: 0 | BC9: 0 | BD9: 0 | BE9: 0 | BF9: 3600 | BJ9: 1800 | BK9: 0 | BL9: 1800 | BM9: 0 | BN9: 0 | BO9: 0 | BP9: 0 | BQ9: 0 | BR9: 0 | BS9: 3600
A10: L-ERP-092 | B10: Dougherty, Chris_CONTRACTORS_EnhanceChargeout001 | D10: =_xlfn.TEXTJOIN("_",FALSE,E10,ERP_8[[#This Row],[Expense Category]],ERP_8[[#This Row],[Project Code*]]) -> Dougherty, Chris_CONTRACTORS_EnhanceChargeout001 | E10: Dougherty, Chris | G10: ERP | H10: Dougherty, Chris | I10: Dougherty, Chris | J10: Maguire, Karla | K10: CONTRACTORS | L10: Enhance Chargeout Cost Centers | N10: 2329946; 2329949 | O10: EnhanceChargeout001 | P10: CHW - Ok ~9500 | S10: None | V10: 0 | W10: -51577 | Z10: 44340 | AA10: -23011 | AB10: -72906 | AC10: 9489 | AD10: -2647 | AE10: 5440 | AF10: 10218.97 | AG10: 0 | AH10: 0 | AI10: 0 | AJ10: 0 | AK10: 0 | AL10: =SUM(Z10:AK10) -> -29076.03 | AM10: =ERP_8[[#This Row],[2026 Working Total]]-ERP_8[[#This Row],[LE2 Final Submission]] -> 22500.97 | AN10: 0 | AO10: =$AE10 - $AN10 -> 5440 | AP10: =SUM(ERP_8[[#This Row],[AP01]:[AP07]])-SUM(ERP_8[[#This Row],[AP01 LE2]:[AP07 LE2]]) -> 22500.97 | AR10: =ERP_8[[#This Row],[2026 Working Total to Budget/LE]]-ERP_8[[#This Row],[Giveback]] -> 22500.97 | AT10: 44340 | AU10: -23011 | AV10: -72906 | AW10: 0 | AX10: 0 | AY10: 0 | AZ10: 0 | BA10: 0 | BB10: 0 | BC10: 0 | BD10: 0 | BE10: 0 | BF10: -51577 | BG10: 44340 | BH10: -23011 | BI10: -72906 | BJ10: 0 | BK10: 0 | BL10: 0 | BM10: 0 | BN10: 0 | BO10: 0 | BP10: 0 | BQ10: 0 | BR10: 0 | BS10: -51577
A11: L-ERP-370 | B11: McCormick, Pete_CONTRACTORS_EnhanceChargeout001 | D11: =_xlfn.TEXTJOIN("_",FALSE,E11,ERP_8[[#This Row],[Expense Category]],ERP_8[[#This Row],[Project Code*]]) -> Dougherty, Chris_CONTRACTORS_EnhanceChargeout001 | E11: Dougherty, Chris | G11: ERP | H11: Dougherty, Chris | I11: McCormick, Pete | J11: Maguire, Karla | K11: CONTRACTORS | L11: Enhance Chargeout Cost Centers | N11: 2329947 | O11: EnhanceChargeout001 | P11: CHW - F/U | S11: None | V11: -694940 | W11: -587120.73 | AA11: -20640.86 | AB11: -10639.87 | AC11: 0.74 | AD11: -75810.34 | AE11: -172301.13 | AF11: 0.43 | AG11: -152040 | AH11: -65840 | AI11: -6640 | AJ11: -72992 | AK11: -146147 | AL11: =SUM(Z11:AK11) -> -723050.03 | AM11: =ERP_8[[#This Row],[2026 Working Total]]-ERP_8[[#This Row],[LE2 Final Submission]] -> -135929.3 | AN11: 0 | AO11: =$AE11 - $AN11 -> -172301.13 | AP11: =SUM(ERP_8[[#This Row],[AP01]:[AP07]])-SUM(ERP_8[[#This Row],[AP01 LE2]:[AP07 LE2]]) -> -67270.3 | AR11: =ERP_8[[#This Row],[2026 Working Total to Budget/LE]]-ERP_8[[#This Row],[Giveback]] -> -135929.3 | AU11: -20640.86 | AV11: -10639.87 | AW11: -55600 | AX11: -6440 | AY11: -43800 | AZ11: -75000 | BA11: -75000 | BB11: -75000 | BC11: -75000 | BD11: -75000 | BE11: -75000 | BF11: -587120.73 | BH11: -20640.86 | BI11: -10639.87 | BJ11: -54600 | BK11: -50000 | BL11: -33840 | BM11: -75000 | BN11: -75000 | BO11: -75000 | BP11: -75000 | BQ11: -75000 | BR11: -75000 | BS11: -619720.73
A12: L-ERP-444 | B12: Meadows, Leslie_CONTRACTORS_EnhanceChargeout001 | D12: =_xlfn.TEXTJOIN("_",FALSE,E12,ERP_8[[#This Row],[Expense Category]],ERP_8[[#This Row],[Project Code*]]) -> Dougherty, Chris_CONTRACTORS_EnhanceChargeout001 | E12: Dougherty, Chris | G12: ERP | H12: Dougherty, Chris | I12: Meadows, Leslie | J12: Maguire, Karla | K12: CONTRACTORS | L12: Enhance Chargeout Cost Centers | N12: 2329948 | O12: EnhanceChargeout001 | P12: CHW - F/U | S12: None | T12: KP - ER #'s in Project Code comments | V12: 0 | W12: -1440 | AA12: -1440 | AB12: 0 | AC12: 0 | AD12: 0 | AE12: -18000 | AF12: 0 | AG12: 0 | AH12: 0 | AI12: 0 | AJ12: 0 | AK12: 0 | AL12: =SUM(Z12:AK12) -> -19440 | AM12: =ERP_8[[#This Row],[2026 Working Total]]-ERP_8[[#This Row],[LE2 Final Submission]] -> -18000 | AN12: 0 | AO12: =$AE12 - $AN12 -> -18000 | AP12: =SUM(ERP_8[[#This Row],[AP01]:[AP07]])-SUM(ERP_8[[#This Row],[AP01 LE2]:[AP07 LE2]]) -> -18000 | AR12: =ERP_8[[#This Row],[2026 Working Total to Budget/LE]]-ERP_8[[#This Row],[Giveback]] -> -18000 | AU12: -1440 | AV12: 0 | AW12: 0 | AX12: 0 | AY12: 0 | AZ12: 0 | BA12: 0 | BB12: 0 | BC12: 0 | BD12: 0 | BE12: 0 | BF12: -1440 | BH12: -1440 | BI12: 0 | BJ12: 0 | BK12: 0 | BL12: 0 | BM12: 0 | BN12: 0 | BO12: 0 | BP12: 0 | BQ12: 0 | BR12: 0 | BS12: -1440
A13: L-ERP-473 | B13: Patel, Nikunj Rohitkumar_CONTRACTORS_EnhanceChargeout001 | D13: =_xlfn.TEXTJOIN("_",FALSE,E13,ERP_8[[#This Row],[Expense Category]],ERP_8[[#This Row],[Project Code*]]) -> Dougherty, Chris_CONTRACTORS_EnhanceChargeout001 | E13: Dougherty, Chris | G13: ERP | H13: Dougherty, Chris | I13: Patel, Nikunj Rohitkumar | J13: Maguire, Karla | K13: CONTRACTORS | L13: Enhance Chargeout Cost Centers | O13: EnhanceChargeout001 | P13: CHW - F/U | S13: None | T13: KP - Where would i be able to get more details on this? Please advise. thank you | V13: 0 | W13: -68766 | AA13: -57216 | AB13: -11550 | AD13: 0 | AE13: 0 | AG13: 0 | AH13: 0 | AI13: 0 | AJ13: 0 | AK13: 0 | AL13: =SUM(Z13:AK13) -> -68766 | AM13: =ERP_8[[#This Row],[2026 Working Total]]-ERP_8[[#This Row],[LE2 Final Submission]] -> 0 | AN13: 0 | AO13: =$AE13 - $AN13 -> 0 | AP13: =SUM(ERP_8[[#This Row],[AP01]:[AP07]])-SUM(ERP_8[[#This Row],[AP01 LE2]:[AP07 LE2]]) -> 0 | AR13: =ERP_8[[#This Row],[2026 Working Total to Budget/LE]]-ERP_8[[#This Row],[Giveback]] -> 0 | AU13: -57216 | AV13: -11550 | AW13: 0 | AX13: 0 | AY13: 0 | AZ13: 0 | BA13: 0 | BB13: 0 | BC13: 0 | BD13: 0 | BE13: 0 | BF13: -68766 | BH13: -57216 | BI13: -11550 | BJ13: 0 | BK13: 0 | BL13: 0 | BM13: 0 | BN13: 0 | BO13: 0 | BP13: 0 | BQ13: 0 | BR13: 0 | BS13: -68766
A14: ERP-026 | B14: Tamavada, Ram_CONTRACTORS_EnhanceChargeout001 | D14: =_xlfn.TEXTJOIN("_",FALSE,E14,ERP_8[[#This Row],[Expense Category]],ERP_8[[#This Row],[Project Code*]]) -> Dougherty, Chris_CONTRACTORS_EnhanceChargeout001 | E14: Dougherty, Chris | G14: ERP | H14: Dougherty, Chris | I14: Tamavada, Ram | J14: Tamavada, Ram | K14: CONTRACTORS | L14: SAP SECURITY CLIENT PROJECTS-IBM | M14: IBM | N14: 2339537 | O14: EnhanceChargeout001 | AC14: 24147 | AD14: -46130 | AE14: -215360 | AF14: 30735.05 | AL14: =SUM(Z14:AK14) -> -206607.95 | AM14: =ERP_8[[#This Row],[2026 Working Total]]-ERP_8[[#This Row],[LE2 Final Submission]] -> -206607.95 | AN14: 0 | AO14: =$AE14 - $AN14 -> -215360 | AP14: =SUM(ERP_8[[#This Row],[AP01]:[AP07]])-SUM(ERP_8[[#This Row],[AP01 LE2]:[AP07 LE2]]) -> -206607.95 | AR14: =ERP_8[[#This Row],[2026 Working Total to Budget/LE]]-ERP_8[[#This Row],[Giveback]] -> -206607.95
A15: ERP-037 | B15: Dougherty, Chris_CONTRACTORS_EP&SCharges001 | D15: =_xlfn.TEXTJOIN("_",FALSE,E15,ERP_8[[#This Row],[Expense Category]],ERP_8[[#This Row],[Project Code*]]) -> Dougherty, Chris_CONTRACTORS_EP&SCharges001 | E15: Dougherty, Chris | G15: ERP | H15: Dougherty, Chris | I15: Dougherty, Chris | J15: Dougherty, Chris | K15: CONTRACTORS | L15: DIGITAL-CITRIX-APPSTREAMING | N15: 2321402 | O15: EP&SCharges001 | AD15: 550 | AE15: 0 | AF15: 0 | AL15: =SUM(Z15:AK15) -> 550 | AM15: =ERP_8[[#This Row],[2026 Working Total]]-ERP_8[[#This Row],[LE2 Final Submission]] -> 550 | AN15: 0 | AO15: =$AE15 - $AN15 -> 0 | AP15: =SUM(ERP_8[[#This Row],[AP01]:[AP07]])-SUM(ERP_8[[#This Row],[AP01 LE2]:[AP07 LE2]]) -> 550 | AR15: =ERP_8[[#This Row],[2026 Working Total to Budget/LE]]-ERP_8[[#This Row],[Giveback]] -> 550
A16: L-ERP-518 | B16: Tamavada, Ram_CONTRACTORS_EP&SCharges001 | D16: =_xlfn.TEXTJOIN("_",FALSE,E16,ERP_8[[#This Row],[Expense Category]],ERP_8[[#This Row],[Project Code*]]) -> Dougherty, Chris_CONTRACTORS_EP&SCharges001 | E16: Dougherty, Chris | G16: ERP | H16: Dougherty, Chris | I16: Tamavada, Ram | J16: Maguire, Karla | K16: CONTRACTORS | L16: Infrastructure Billing Charges | N16: 2320843;2321403 | O16: EP&SCharges001 | P16: CHW - Ok | Q16: N/A | S16: EP&S | V16: 0 | W16: 1080 | Z16: 360 | AA16: 360 | AB16: 360 | AC16: 0 | AD16: 0 | AE16: 0 | AF16: 0 | AG16: 0 | AH16: 0 | AI16: 0 | AJ16: 0 | AK16: 0 | AL16: =SUM(Z16:AK16) -> 1080 | AM16: =ERP_8[[#This Row],[2026 Working Total]]-ERP_8[[#This Row],[LE2 Final Submission]] -> 0 | AN16: 0 | AO16: =$AE16 - $AN16 -> 0 | AP16: =SUM(ERP_8[[#This Row],[AP01]:[AP07]])-SUM(ERP_8[[#This Row],[AP01 LE2]:[AP07 LE2]]) -> 0 | AR16: =ERP_8[[#This Row],[2026 Working Total to Budget/LE]]-ERP_8[[#This Row],[Giveback]] -> 0 | AT16: 360 | AU16: 360 | AV16: 360 | AW16: 0 | AX16: 0 | AY16: 0 | AZ16: 0 | BA16: 0 | BB16: 0 | BC16: 0 | BD16: 0 | BE16: 0 | BF16: 1080 | BG16: 360 | BH16: 360 | BI16: 360 | BJ16: 0 | BK16: 0 | BL16: 0 | BM16: 0 | BN16: 0 | BO16: 0 | BP16: 0 | BQ16: 0 | BR16: 0 | BS16: 1080
A17: L-ERP-439 | B17: Meadows, Leslie_CONTRACTORS_IT-CTR0044-OG-US-00 | D17: =_xlfn.TEXTJOIN("_",FALSE,E17,ERP_8[[#This Row],[Expense Category]],ERP_8[[#This Row],[Project Code*]]) -> Dougherty, Chris_CONTRACTORS_IT-CTR0044-OG-US-00 | E17: Dougherty, Chris | G17: ERP | H17: Dougherty, Chris | I17: Meadows, Leslie | J17: Maguire, Karla | K17: CONTRACTORS | L17: SSCS Services (Karla)_XFR0954 & XFR0934 & XFR0932 & XFR0913 & XFR0940 & XFR0941 | N17: 2321511 | O17: IT-CTR0044-OG-US-00 | S17: None | V17: 551723.04 | W17: 460642 | AC17: 0 | AD17: 29102.65 | AE17: 67355.9 | AF17: 34698.83 | AG17: 81341 | AH17: =42525+20000 -> 62525 | AI17: 48020 | AJ17: 42525 | AK17: 39926 | AL17: =SUM(Z17:AK17) -> 405494.38 | AM17: =ERP_8[[#This Row],[2026 Working Total]]-ERP_8[[#This Row],[LE2 Final Submission]] -> -55147.62 | AN17: 0 | AO17: =$AE17 - $AN17 -> 67355.9 | AP17: =SUM(ERP_8[[#This Row],[AP01]:[AP07]])-SUM(ERP_8[[#This Row],[AP01 LE2]:[AP07 LE2]]) -> -138125.62 | AQ17: -91081 | AR17: =ERP_8[[#This Row],[2026 Working Total to Budget/LE]]-ERP_8[[#This Row],[Giveback]] -> 35933.38 | AS17: testing factory adjustment | AW17: 36666 | AX17: 141912 | AY17: 49848 | AZ17: 40857 | BA17: 40681 | BB17: 37645 | BC17: 37694 | BD17: 37645 | BE17: 37694 | BF17: 460642 | BJ17: 61303 | BK17: 61303 | BL17: 61303 | BM17: 61303 | BN17: 61303 | BO17: 61303 | BP17: 61303 | BQ17: 61303 | BR17: 61303 | BS17: 551727
A18: L-ERP-323 | B18: Maguire, Karla_CONTRACTORS_IT-CTR0067-OG-CR-00 | D18: =_xlfn.TEXTJOIN("_",FALSE,E18,ERP_8[[#This Row],[Expense Category]],ERP_8[[#This Row],[Project Code*]]) -> Dougherty, Chris_CONTRACTORS_IT-CTR0067-OG-CR-00 | E18: Dougherty, Chris | G18: ERP | H18: Dougherty, Chris | I18: Maguire, Karla | J18: Maguire, Karla | K18: CONTRACTORS | L18: *RonMendler*_EPS203076 - Edicom CR Recepcion Enero-Diciembre 2025 | O18: IT-CTR0067-OG-CR-00 | S18: None | V18: 0 | W18: 214.49 | Z18: 215.71 | AA18: -1.22 | AB18: 0 | AD18: 0 | AE18: 0 | AG18: 0 | AH18: 0 | AI18: 0 | AJ18: 0 | AK18: 0 | AL18: =SUM(Z18:AK18) -> 214.49 | AM18: =ERP_8[[#This Row],[2026 Working Total]]-ERP_8[[#This Row],[LE2 Final Submission]] -> 0 | AN18: 0 | AO18: =$AE18 - $AN18 -> 0 | AP18: =SUM(ERP_8[[#This Row],[AP01]:[AP07]])-SUM(ERP_8[[#This Row],[AP01 LE2]:[AP07 LE2]]) -> 0 | AR18: =ERP_8[[#This Row],[2026 Working Total to Budget/LE]]-ERP_8[[#This Row],[Giveback]] -> 0 | AT18: 215.71 | AU18: -1.22 | AV18: 0 | AW18: 0 | AX18: 0 | AY18: 0 | AZ18: 0 | BA18: 0 | BB18: 0 | BC18: 0 | BD18: 0 | BE18: 0 | BF18: 214.49 | BG18: 215.71 | BH18: -1.22 | BI18: 0 | BJ18: 0 | BK18: 0 | BL18: 0 | BM18: 0 | BN18: 0 | BO18: 0 | BP18: 0 | BQ18: 0 | BR18: 0 | BS18: 214.49
A19: L-ERP-348 | B19: McCormick, Pete_CONTRACTORS_IT-CTR0093-OG-US-00 | D19: =_xlfn.TEXTJOIN("_",FALSE,E19,ERP_8[[#This Row],[Expense Category]],ERP_8[[#This Row],[Project Code*]]) -> Dougherty, Chris_CONTRACTORS_IT-CTR0093-OG-US-00 | E19: Dougherty, Chris | G19: ERP | H19: Dougherty, Chris | I19: McCormick, Pete | J19: Maguire, Karla | K19: CONTRACTORS | L19: SAP Platform Engineers (Judge) | N19: 2329614 | O19: IT-CTR0093-OG-US-00 | Q19: Multiple | S19: 2024 Transfer | V19: 345518.86 | W19: 345670.24 | Z19: 35812 | AA19: 40109.44 | AB19: 50136.8 | AC19: 40109.45 | AD19: 40109.45 | AE19: 29136.78 | AF19: 40109.45 | AG19: 14015 | AH19: 14015 | AI19: 14015 | AJ19: 14015 | AK19: 14015 | AL19: =SUM(Z19:AK19) -> 345598.37 | AM19: =ERP_8[[#This Row],[2026 Working Total]]-ERP_8[[#This Row],[LE2 Final Submission]] -> -71.87 | AN19: 0 | AO19: =$AE19 - $AN19 -> 29136.78 | AP19: =SUM(ERP_8[[#This Row],[AP01]:[AP07]])-SUM(ERP_8[[#This Row],[AP01 LE2]:[AP07 LE2]]) -> 28658.13 | AR19: =ERP_8[[#This Row],[2026 Working Total to Budget/LE]]-ERP_8[[#This Row],[Giveback]] -> -71.87 | AT19: 35812 | AU19: 40109.44 | AV19: 50136.8 | AW19: 40000 | AX19: 28897 | AY19: 28897 | AZ19: 23013 | BA19: 22297 | BB19: 19127 | BC19: 19127 | BD19: 19127 | BE19: 19127 | BF19: 345670.24 | BG19: 35812 | BH19: 40109.44 | BI19: 50136.8 | BJ19: 40000 | BK19: 28897 | BL19: 28897 | BM19: 23013 | BN19: 22297 | BO19: 22297 | BP19: 22297 | BQ19: 22297 | BR19: 22297 | BS19: 358350.24
A20: L-ERP-108 | B20: Dougherty, Chris_CONTRACTORS_IT-CTR0094-OG-US-00 | D20: =_xlfn.TEXTJOIN("_",FALSE,E20,ERP_8[[#This Row],[Expense Category]],ERP_8[[#This Row],[Project Code*]]) -> Dougherty, Chris_CONTRACTORS_IT-CTR0094-OG-US-00 | E20: Dougherty, Chris | G20: ERP | H20: Dougherty, Chris | I20: Dougherty, Chris | J20: Maguire, Karla | K20: CONTRACTORS | L20: BPAI Axway B2Bi - L4 Engineer (ML-0024) | M20: JUDGE TECHNICAL STAFFING | N20: 2137469 | O20: IT-CTR0094-OG-US-00 | Q20: 9501146792 | S20: SAP | V20: 216000 | W20: 197423.06 | Z20: 14166 | AA20: 18835.37 | AB20: 16863.69 | AC20: 15866.15 | AD20: 15866.16 | AE20: 19832.69 | AF20: 15866.15 | AG20: 17000 | AH20: 18134 | AI20: 17000 | AJ20: 17000 | AK20: 17000 | AL20: =SUM(Z20:AK20) -> 203430.21 | AM20: =ERP_8[[#This Row],[2026 Working Total]]-ERP_8[[#This Row],[LE2 Final Submission]] -> 6007.15 | AN20: 0 | AO20: =$AE20 - $AN20 -> 19832.69 | AP20: =SUM(ERP_8[[#This Row],[AP01]:[AP07]])-SUM(ERP_8[[#This Row],[AP01 LE2]:[AP07 LE2]]) -> 4873.15 | AR20: =ERP_8[[#This Row],[2026 Working Total to Budget/LE]]-ERP_8[[#This Row],[Giveback]] -> 6007.15 | AT20: 14166 | AU20: 18835.37 | AV20: 16863.69 | AW20: 11558 | AX20: 17000 | AY20: 17000 | AZ20: 17000 | BA20: 17000 | BB20: 17000 | BC20: 17000 | BD20: 17000 | BE20: 17000 | BF20: 197423.06 | BG20: 14166 | BH20: 18835.37 | BI20: 16863.69 | BJ20: 18000 | BK20: 18000 | BL20: 18000 | BM20: 18000 | BN20: 18000 | BO20: 18000 | BP20: 18000 | BQ20: 18000 | BR20: 18000 | BS20: 211865.06
A21: L-ERP-109 | B21: Dougherty, Chris_CONTRACTORS_IT-CTR0096-OG-US-00 | D21: =_xlfn.TEXTJOIN("_",FALSE,E21,ERP_8[[#This Row],[Expense Category]],ERP_8[[#This Row],[Project Code*]]) -> Dougherty, Chris_CONTRACTORS_IT-CTR0096-OG-US-00 | E21: Dougherty, Chris | G21: ERP | H21: Dougherty, Chris | I21: Dougherty, Chris | J21: Maguire, Karla | K21: CONTRACTORS | L21: SAP PI L4 Engineer | M21: MPHASIS CORPORATION | N21: 2321402 | O21: IT-CTR0096-OG-US-00 | Q21: 9501172399 | S21: SAP | V21: 237888 | W21: 236045.4 | Z21: 16372 | AA21: 18336.62 | AB21: 22920.78 | AC21: 18336.63 | AD21: 18336.63 | AE21: 22920.78 | AF21: 18336.63 | AG21: =19824+1487 -> 21311 | AH21: 19824 | AI21: 19824 | AJ21: 19824 | AK21: 19824 | AL21: =SUM(Z21:AK21) -> 236167.07 | AM21: =ERP_8[[#This Row],[2026 Working Total]]-ERP_8[[#This Row],[LE2 Final Submission]] -> 121.67 | AN21: 0 | AO21: =$AE21 - $AN21 -> 22920.78 | AP21: =SUM(ERP_8[[#This Row],[AP01]:[AP07]])-SUM(ERP_8[[#This Row],[AP01 LE2]:[AP07 LE2]]) -> -1365.33 | AR21: =ERP_8[[#This Row],[2026 Working Total to Budget/LE]]-ERP_8[[#This Row],[Giveback]] -> 121.67 | AT21: 16372 | AU21: 18336.62 | AV21: 22920.78 | AW21: 19824 | AX21: 19824 | AY21: 19824 | AZ21: 19824 | BA21: 19824 | BB21: 19824 | BC21: 19824 | BD21: 19824 | BE21: 19824 | BF21: 236045.4 | BG21: 16372 | BH21: 18336.62 | BI21: 22920.78 | BJ21: 19824 | BK21: 19824 | BL21: 19824 | BM21: 19824 | BN21: 19824 | BO21: 19824 | BP21: 19824 | BQ21: 19824 | BR21: 19824 | BS21: 236045.4
A22: L-ERP-050 | B22: Dougherty, Chris_CONTRACTORS_IT-CTR0097-OG-US-00 | D22: =_xlfn.TEXTJOIN("_",FALSE,E22,ERP_8[[#This Row],[Expense Category]],ERP_8[[#This Row],[Project Code*]]) -> Dougherty, Chris_CONTRACTORS_IT-CTR0097-OG-US-00 | E22: Dougherty, Chris | G22: ERP | H22: Dougherty, Chris | I22: Dougherty, Chris | J22: Maguire, Karla | K22: CONTRACTORS | L22: BPAI IBM B2Bi - GMFT L4 Engineer (ML-0738) | M22: JUDGE TECHNICAL STAFFING | N22: 2321402 | O22: IT-CTR0097-OG-US-00 | Q22: 9501146194 | S22: 2024 Transfer | V22: 230004 | W22: 211390.3 | Z22: 14973 | AA22: 18162.76 | AB22: 19567.54 | AC22: 16769.23 | AD22: 16769.23 | AE22: -21713.76 | AF22: 0 | AG22: 20928 | AH22: 20928 | AI22: 20928 | AJ22: 20928 | AK22: 20928 | AL22: =SUM(Z22:AK22) -> 169168 | AM22: =ERP_8[[#This Row],[2026 Working Total]]-ERP_8[[#This Row],[LE2 Final Submission]] -> -42222.3 | AN22: 0 | AO22: =$AE22 - $AN22 -> -21713.76 | AP22: =SUM(ERP_8[[#This Row],[AP01]:[AP07]])-SUM(ERP_8[[#This Row],[AP01 LE2]:[AP07 LE2]]) -> -59662.3 | AR22: =ERP_8[[#This Row],[2026 Working Total to Budget/LE]]-ERP_8[[#This Row],[Giveback]] -> -42222.3 | AT22: 14973 | AU22: 18162.76 | AV22: 19567.54 | AW22: 19167 | AX22: 17440 | AY22: 17440 | AZ22: 17440 | BA22: 17440 | BB22: 17440 | BC22: 17440 | BD22: 17440 | BE22: 17440 | BF22: 211390.3 | BG22: 14973 | BH22: 18162.76 | BI22: 19567.54 | BJ22: 19167 | BK22: 19167 | BL22: 19167 | BM22: 19167 | BN22: 19167 | BO22: 19167 | BP22: 19167 | BQ22: 19167 | BR22: 19167 | BS22: 225206.3
A23: L-ERP-051 | B23: Dougherty, Chris_CONTRACTORS_IT-CTR0098-OG-US-00 | D23: =_xlfn.TEXTJOIN("_",FALSE,E23,ERP_8[[#This Row],[Expense Category]],ERP_8[[#This Row],[Project Code*]]) -> Dougherty, Chris_CONTRACTORS_IT-CTR0098-OG-US-00 | E23: Dougherty, Chris | G23: ERP | H23: Dougherty, Chris | I23: Dougherty, Chris | J23: Maguire, Karla | K23: CONTRACTORS | L23: BPAI IBM B2Bi - EDI L4 Engineer (ML-0728) | M23: COMBINED COMPUTER RESOURCES INC | N23: 2321402 | O23: IT-CTR0098-OG-US-00 | Q23: 9501146188 | S23: 2024 Transfer | V23: 187200 | W23: 185657.15 | Z23: 12857 | AA23: 18823.15 | AB23: 13577 | AC23: 14400 | AD23: 17263 | AE23: 36956.74 | AF23: -1531.12 | AG23: 19743 | AH23: 19743 | AI23: 19743 | AJ23: 19743 | AK23: 19743 | AL23: =SUM(Z23:AK23) -> 211060.77 | AM23: =ERP_8[[#This Row],[2026 Working Total]]-ERP_8[[#This Row],[LE2 Final Submission]] -> 25403.62 | AN23: 0 | AO23: =$AE23 - $AN23 -> 36956.74 | AP23: =SUM(ERP_8[[#This Row],[AP01]:[AP07]])-SUM(ERP_8[[#This Row],[AP01 LE2]:[AP07 LE2]]) -> 4688.62 | AR23: =ERP_8[[#This Row],[2026 Working Total to Budget/LE]]-ERP_8[[#This Row],[Giveback]] -> 25403.62 | AT23: 12857 | AU23: 18823.15 | AV23: 13577 | AW23: 15600 | AX23: 15600 | AY23: 15600 | AZ23: 15600 | BA23: 15600 | BB23: 15600 | BC23: 15600 | BD23: 15600 | BE23: 15600 | BF23: 185657.15 | BG23: 12857 | BH23: 18823.15 | BI23: 13577 | BJ23: 15600 | BK23: 15600 | BL23: 15600 | BM23: 15600 | BN23: 15600 | BO23: 15600 | BP23: 15600 | BQ23: 15600 | BR23: 15600 | BS23: 185657.15
A24: L-ERP-052 | B24: Dougherty, Chris_CONTRACTORS_IT-CTR0099-OG-US-00 | D24: =_xlfn.TEXTJOIN("_",FALSE,E24,ERP_8[[#This Row],[Expense Category]],ERP_8[[#This Row],[Project Code*]]) -> Dougherty, Chris_CONTRACTORS_IT-CTR0099-OG-US-00 | E24: Dougherty, Chris | G24: ERP | H24: Dougherty, Chris | I24: Dougherty, Chris | J24: Maguire, Karla | K24: CONTRACTORS | L24: BPAI MQ/MB - L4 Engineer (ML-0730) | M24: ACCENTURE LLP | N24: 2321402 | O24: IT-CTR0099-OG-US-00 | Q24: 9501155447 | S24: 2024 Transfer | V24: 141310.95 | W24: 132735.51 | Z24: 9654 | AA24: 14825.74 | AB24: 12851.77 | AC24: 7463.62 | AD24: 16343.61 | AE24: 13997.28 | AF24: 16825.13 | AG24: 6534 | AH24: 6534 | AI24: 6534 | AJ24: 6534 | AK24: 6534 | AL24: =SUM(Z24:AK24) -> 124631.15 | AM24: =ERP_8[[#This Row],[2026 Working Total]]-ERP_8[[#This Row],[LE2 Final Submission]] -> -8104.36 | AN24: 0 | AO24: =$AE24 - $AN24 -> 13997.28 | AP24: =SUM(ERP_8[[#This Row],[AP01]:[AP07]])-SUM(ERP_8[[#This Row],[AP01 LE2]:[AP07 LE2]]) -> 12789.64 | AR24: =ERP_8[[#This Row],[2026 Working Total to Budget/LE]]-ERP_8[[#This Row],[Giveback]] -> -8104.36 | AT24: 9654 | AU24: 14825.74 | AV24: 12851.77 | AW24: 11942 | AX24: 10718 | AY24: 9590 | AZ24: 9590 | BA24: 10718 | BB24: 11090 | BC24: 11090 | BD24: 9590 | BE24: 11076 | BF24: 132735.51 | BG24: 9654 | BH24: 14825.74 | BI24: 12851.77 | BJ24: 10870.45 | BK24: 11986 | BL24: 11986 | BM24: 11986 | BN24: 11986 | BO24: 11986 | BP24: 11986 | BQ24: 11986 | BR24: 11986 | BS24: 144089.96
A25: L-ERP-081 | B25: Dougherty, Chris_CONTRACTORS_IT-CTR0101-OG-US-00 | D25: =_xlfn.TEXTJOIN("_",FALSE,E25,ERP_8[[#This Row],[Expense Category]],ERP_8[[#This Row],[Project Code*]]) -> Dougherty, Chris_CONTRACTORS_IT-CTR0101-OG-US-00 | E25: Dougherty, Chris | G25: ERP | H25: Dougherty, Chris | I25: Dougherty, Chris | J25: Maguire, Karla | K25: CONTRACTORS | L25: BPAI IBM B2Bi - GMFT L4 Engineer (ML-0732) | M25: INFOSYS LIMITED | N25: 2321402 | O25: IT-CTR0101-OG-US-00 | Q25: 9501140303 | S25: None | V25: 97500 | W25: 90751.67 | Z25: 10704.42 | AA25: 11988.8 | AB25: 9558.45 | AC25: 6923.07 | AD25: 8819.08 | AE25: 6012.11 | AF25: 6012.51 | AG25: 6000 | AH25: 6000 | AI25: 7500 | AJ25: 7500 | AK25: 7500 | AL25: =SUM(Z25:AK25) -> 94518.44 | AM25: =ERP_8[[#This Row],[2026 Working Total]]-ERP_8[[#This Row],[LE2 Final Submission]] -> 3766.77 | AN25: 0 | AO25: =$AE25 - $AN25 -> 6012.11 | AP25: =SUM(ERP_8[[#This Row],[AP01]:[AP07]])-SUM(ERP_8[[#This Row],[AP01 LE2]:[AP07 LE2]]) -> 3766.77 | AR25: =ERP_8[[#This Row],[2026 Working Total to Budget/LE]]-ERP_8[[#This Row],[Giveback]] -> 3766.77 | AT25: 10704.42 | AU25: 11988.8 | AV25: 9558.45 | AW25: 6000 | AX25: 6000 | AY25: 6000 | AZ25: 6000 | BA25: 6000 | BB25: 6000 | BC25: 7500 | BD25: 7500 | BE25: 7500 | BF25: 90751.67 | BG25: 10704.42 | BH25: 11988.8 | BI25: 9558.45 | BJ25: 8125 | BK25: 8125 | BL25: 8125 | BM25: 8125 | BN25: 8125 | BO25: 8125 | BP25: 8125 | BQ25: 8125 | BR25: 8125 | BS25: 105376.67
A26: L-ERP-082 | B26: Dougherty, Chris_CONTRACTORS_IT-CTR0102-OG-US-00 | D26: =_xlfn.TEXTJOIN("_",FALSE,E26,ERP_8[[#This Row],[Expense Category]],ERP_8[[#This Row],[Project Code*]]) -> Dougherty, Chris_CONTRACTORS_IT-CTR0102-OG-US-00 | E26: Dougherty, Chris | G26: ERP | H26: Dougherty, Chris | I26: Dougherty, Chris | J26: Maguire, Karla | K26: CONTRACTORS | L26: BPAI AutoSys/UC4 - L4 Engineer (ML-0733) | M26: INFOSYS LIMITED | N26: 2321402 | O26: IT-CTR0102-OG-US-00 | Q26: 9501145077 | S26: None | V26: 107910 | W26: 99679.13 | Z26: 6841 | AA26: 9759.2 | AB26: 7478.93 | AC26: 7661.53 | AD26: 9759.54 | AE26: 8299.79 | AF26: 6840.67 | AG26: 9300 | AH26: 8300 | AI26: 8300 | AJ26: 8300 | AK26: 8300 | AL26: =SUM(Z26:AK26) -> 99140.66 | AM26: =ERP_8[[#This Row],[2026 Working Total]]-ERP_8[[#This Row],[LE2 Final Submission]] -> -538.47 | AN26: 0 | AO26: =$AE26 - $AN26 -> 8299.79 | AP26: =SUM(ERP_8[[#This Row],[AP01]:[AP07]])-SUM(ERP_8[[#This Row],[AP01 LE2]:[AP07 LE2]]) -> -1038.47 | AR26: =ERP_8[[#This Row],[2026 Working Total to Budget/LE]]-ERP_8[[#This Row],[Giveback]] -> -538.47 | AT26: 6841 | AU26: 9759.2 | AV26: 7478.93 | AW26: 8400 | AX26: 8400 | AY26: 8400 | AZ26: 8400 | BA26: 8400 | BB26: 8400 | BC26: 8400 | BD26: 8400 | BE26: 8400 | BF26: 99679.13 | BG26: 6841 | BH26: 9759.2 | BI26: 7478.93 | BJ26: 8992.5 | BK26: 8992.5 | BL26: 8992.5 | BM26: 8992.5 | BN26: 8992.5 | BO26: 8992.5 | BP26: 8992.5 | BQ26: 8992.5 | BR26: 8992.5 | BS26: 105011.63
A27: L-ERP-083 | B27: Dougherty, Chris_CONTRACTORS_IT-CTR0103-OG-US-00 | D27: =_xlfn.TEXTJOIN("_",FALSE,E27,ERP_8[[#This Row],[Expense Category]],ERP_8[[#This Row],[Project Code*]]) -> Dougherty, Chris_CONTRACTORS_IT-CTR0103-OG-US-00 | E27: Dougherty, Chris | G27: ERP | H27: Dougherty, Chris | I27: Dougherty, Chris | J27: Maguire, Karla | K27: CONTRACTORS | L27: BPAI Cross-Functional Audit Specialist (ML-0735) | M27: JUDGE TECHNICAL STAFFING | N27: 2321402 | O27: IT-CTR0103-OG-US-00 | Q27: 9501145076 | S27: None | V27: 87360 | W27: 83873.7 | Z27: 11538 | AA27: 8258.77 | AB27: 1796.93 | AC27: 5175.54 | AD27: 10565.53 | AE27: 3972.93 | AF27: 8113.89 | AG27: 13000 | AH27: 7000 | AI27: 7000 | AJ27: 7000 | AK27: 7000 | AL27: =SUM(Z27:AK27) -> 90421.59 | AM27: =ERP_8[[#This Row],[2026 Working Total]]-ERP_8[[#This Row],[LE2 Final Submission]] -> 6547.89 | AN27: 0 | AO27: =$AE27 - $AN27 -> 3972.93 | AP27: =SUM(ERP_8[[#This Row],[AP01]:[AP07]])-SUM(ERP_8[[#This Row],[AP01 LE2]:[AP07 LE2]]) -> 827.89 | AR27: =ERP_8[[#This Row],[2026 Working Total to Budget/LE]]-ERP_8[[#This Row],[Giveback]] -> 6547.89 | AT27: 11538 | AU27: 8258.77 | AV27: 1796.93 | AW27: 6000 | AX27: 7000 | AY27: 7000 | AZ27: 7000 | BA27: 7000 | BB27: 7000 | BC27: 7000 | BD27: 7000 | BE27: 7280 | BF27: 83873.7 | BG27: 11538 | BH27: 8258.77 | BI27: 1796.93 | BJ27: 7280 | BK27: 7280 | BL27: 7280 | BM27: 7280 | BN27: 7280 | BO27: 7280 | BP27: 7280 | BQ27: 7280 | BR27: 7280 | BS27: 87113.7
A28: L-ERP-440 | B28: Meadows, Leslie_CONTRACTORS_IT-CTR0105-OG-US-00 | D28: =_xlfn.TEXTJOIN("_",FALSE,E28,ERP_8[[#This Row],[Expense Category]],ERP_8[[#This Row],[Project Code*]]) -> Dougherty, Chris_CONTRACTORS_IT-CTR0105-OG-US-00 | E28: Dougherty, Chris | G28: ERP | H28: Dougherty, Chris | I28: Meadows, Leslie | J28: Maguire, Karla | K28: CONTRACTORS | L28: Chargeback / ERP Change Management Solution PA APP | O28: IT-CTR0105-OG-US-00 | Q28: N | S28: None | T28: KP - 'Services Discontinued as per Leslie. | V28: 750 | W28: 0 | AD28: 0 | AE28: 0 | AG28: 0 | AH28: 0 | AI28: 0 | AJ28: 0 | AK28: 0 | AL28: =SUM(Z28:AK28) -> 0 | AM28: =ERP_8[[#This Row],[2026 Working Total]]-ERP_8[[#This Row],[LE2 Final Submission]] -> 0 | AN28: 0 | AO28: =$AE28 - $AN28 -> 0 | AP28: =SUM(ERP_8[[#This Row],[AP01]:[AP07]])-SUM(ERP_8[[#This Row],[AP01 LE2]:[AP07 LE2]]) -> 0 | AQ28: -750 | AR28: =ERP_8[[#This Row],[2026 Working Total to Budget/LE]]-ERP_8[[#This Row],[Giveback]] -> 750 | AS28: Services Discontinued as per Leslie - Kinjal | BF28: 0 | BJ28: 62.5 | BK28: 62.5 | BL28: 62.5 | BM28: 62.5 | BN28: 62.5 | BO28: 62.5 | BP28: 62.5 | BQ28: 62.5 | BR28: 62.5 | BS28: 562.5
A29: L-ERP-366 | B29: McCormick, Pete_CONTRACTORS_IT-CTR0130-OG-US-00 | D29: =_xlfn.TEXTJOIN("_",FALSE,E29,ERP_8[[#This Row],[Expense Category]],ERP_8[[#This Row],[Project Code*]]) -> Dougherty, Chris_CONTRACTORS_IT-CTR0130-OG-US-00 | E29: Dougherty, Chris | G29: ERP | H29: Dougherty, Chris | I29: McCormick, Pete | J29: Maguire, Karla | K29: CONTRACTORS | L29: SAP Basis Engineering Projects (IBM) | N29: 2329614 | O29: IT-CTR0130-OG-US-00 | Q29: 9501143253 | S29: None | T29: PO 9501143253 ($357k) | V29: 357000 | W29: 356999.8 | Z29: 24570 | AA29: 27517.44 | AB29: 34397.36 | AC29: 27517.89 | AD29: 27517.89 | AE29: 34397.36 | AF29: 27517.89 | AG29: 29750 | AH29: 34565 | AI29: 29750 | AJ29: 29750 | AK29: 29750 | AL29: =SUM(Z29:AK29) -> 357000.83 | AM29: =ERP_8[[#This Row],[2026 Working Total]]-ERP_8[[#This Row],[LE2 Final Submission]] -> 1.03 | AN29: 0 | AO29: =$AE29 - $AN29 -> 34397.36 | AP29: =SUM(ERP_8[[#This Row],[AP01]:[AP07]])-SUM(ERP_8[[#This Row],[AP01 LE2]:[AP07 LE2]]) -> -4813.97 | AR29: =ERP_8[[#This Row],[2026 Working Total to Budget/LE]]-ERP_8[[#This Row],[Giveback]] -> 1.03 | AT29: 24570 | AU29: 27517.44 | AV29: 34397.36 | AW29: 32515 | AX29: 29750 | AY29: 29750 | AZ29: 29750 | BA29: 29750 | BB29: 29750 | BC29: 29750 | BD29: 29750 | BE29: 29750 | BF29: 356999.8 | BG29: 24570 | BH29: 27517.44 | BI29: 34397.36 | BJ29: 37163 | BK29: 29750 | BL29: 29750 | BM29: 29750 | BN29: 29750 | BO29: 29750 | BP29: 29750 | BQ29: 29750 | BR29: 29750 | BS29: 361647.8
A30: L-ERP-084 | B30: Dougherty, Chris_CONTRACTORS_IT-CTR0132-OT-US-00 | D30: =_xlfn.TEXTJOIN("_",FALSE,E30,ERP_8[[#This Row],[Expense Category]],ERP_8[[#This Row],[Project Code*]]) -> Dougherty, Chris_CONTRACTORS_IT-CTR0132-OT-US-00 | E30: Dougherty, Chris | G30: ERP | H30: Dougherty, Chris | I30: Dougherty, Chris | J30: Maguire, Karla | K30: CONTRACTORS | L30: 2026 SAP Max Attention Days | M30: Prepaid - SAP AMERICA INC | N30: 2321402 | O30: IT-CTR0132-OT-US-00 | Q30: 9501158603 | S30: None | T30: 5/7 CHW - Updated for soft close on prepaid at 137,279 monthly or AP03 1,647,350 Invoice | V30: 1678341.6 | W30: 1647348.4 | Z30: 113142.14 | AA30: 160853.86 | AB30: 137841.36 | AC30: 0 | AD30: 274558.24 | AE30: 137279.12 | AF30: 0 | AG30: =136998-136998+137279+137279 -> 274558 | AH30: =136998-136998+137279 -> 137279 | AI30: =136998-136998 -> 0 | AJ30: =136998-136998+137279+137279 -> 274558 | AK30: =136998-136998+137279 -> 137279 | AL30: =SUM(Z30:AK30) -> 1647348.7 | AM30: =ERP_8[[#This Row],[2026 Working Total]]-ERP_8[[#This Row],[LE2 Final Submission]] -> 0.36 | AN30: 0 | AO30: =$AE30 - $AN30 -> 137279.12 | AP30: =SUM(ERP_8[[#This Row],[AP01]:[AP07]])-SUM(ERP_8[[#This Row],[AP01 LE2]:[AP07 LE2]]) -> 0.36 | AR30: =ERP_8[[#This Row],[2026 Working Total to Budget/LE]]-ERP_8[[#This Row],[Giveback]] -> 0.36 | AS30: 5/7 CHW - Diff is prepaid amort on invoiced amt | AT30: 113142.14 | AU30: 160853.86 | AV30: 137841.36 | AW30: 0 | AX30: 274558 | AY30: 137279 | AZ30: 0 | BA30: 274558 | BB30: 137279 | BC30: 0 | BD30: 274558 | BE30: 137279 | BF30: 1647348.4 | BG30: 113142.14 | BH30: 160853.86 | BI30: 137841.36 | BJ30: 136998 | BK30: 136998 | BL30: 136998 | BM30: 136998 | BN30: 136998 | BO30: 136998 | BP30: 136998 | BQ30: 136998 | BR30: 136998 | BS30: 1644819.4
A31: N-ERP-503 | B31: Dougherty, Chris_CONTRACTORS_IT-CTR0132-OT-US-00/BDC | D31: =_xlfn.TEXTJOIN("_",FALSE,E31,ERP_8[[#This Row],[Expense Category]],ERP_8[[#This Row],[Project Code*]]) -> Dougherty, Chris_CONTRACTORS_IT-CTR0132-OT-US-00/BDC | E31: Dougherty, Chris | G31: ERP | H31: Dougherty, Chris | I31: Dougherty, Chris | J31: Maguire, Karla | K31: CONTRACTORS | L31: BDC Reclass - 2026 SAP Max Attention Days | O31: IT-CTR0132-OT-US-00/BDC | Q31: 9501158603 | S31: None | V31: =-213108+213108 -> 0 | W31: 0 | AD31: 0 | AE31: 0 | AG31: 0 | AH31: 0 | AI31: 0 | AJ31: 0 | AL31: =SUM(Z31:AK31) -> 0 | AM31: =ERP_8[[#This Row],[2026 Working Total]]-ERP_8[[#This Row],[LE2 Final Submission]] -> 0 | AN31: 0 | AO31: =$AE31 - $AN31 -> 0 | AP31: =SUM(ERP_8[[#This Row],[AP01]:[AP07]])-SUM(ERP_8[[#This Row],[AP01 LE2]:[AP07 LE2]]) -> 0 | AR31: =ERP_8[[#This Row],[2026 Working Total to Budget/LE]]-ERP_8[[#This Row],[Giveback]] -> 0 | AW31: 0 | AX31: 0 | AY31: 0 | AZ31: 0 | BA31: 0 | BB31: 0 | BC31: 0 | BD31: 0 | BF31: 0 | BG31: 0 | BH31: 0 | BI31: 0 | BJ31: 0 | BK31: 0 | BL31: -213108 | BM31: 0 | BN31: 0 | BO31: 0 | BP31: 0 | BQ31: 0 | BR31: 0 | BS31: =SUM(ERP_8[[#This Row],[2026 AP01]:[2026 AP12]]) -> -213108
A32: N-ERP-504 | B32: Dougherty, Chris_CONTRACTORS_IT-CTR0132-OT-US-00/Colalborate 360 | D32: =_xlfn.TEXTJOIN("_",FALSE,E32,ERP_8[[#This Row],[Expense Category]],ERP_8[[#This Row],[Project Code*]]) -> Dougherty, Chris_CONTRACTORS_IT-CTR0132-OT-US-00/Colalborate 360 | E32: Dougherty, Chris | G32: ERP | H32: Dougherty, Chris | I32: Dougherty, Chris | J32: Maguire, Karla | K32: CONTRACTORS | L32: Colalborate 360 Reclass - 2026 SAP Max Attention Days | O32: IT-CTR0132-OT-US-00/Colalborate 360 | Q32: 9501158603 | S32: None | V32: =76110+-76110 -> 0 | W32: 0 | AD32: 0 | AE32: 0 | AG32: 0 | AH32: 0 | AI32: 0 | AJ32: 0 | AL32: =SUM(Z32:AK32) -> 0 | AM32: =ERP_8[[#This Row],[2026 Working Total]]-ERP_8[[#This Row],[LE2 Final Submission]] -> 0 | AN32: 0 | AO32: =$AE32 - $AN32 -> 0 | AP32: =SUM(ERP_8[[#This Row],[AP01]:[AP07]])-SUM(ERP_8[[#This Row],[AP01 LE2]:[AP07 LE2]]) -> 0 | AR32: =ERP_8[[#This Row],[2026 Working Total to Budget/LE]]-ERP_8[[#This Row],[Giveback]] -> 0 | AW32: 0 | AX32: 0 | AY32: 0 | AZ32: 0 | BA32: 0 | BB32: 0 | BC32: 0 | BD32: 0 | BF32: 0 | BG32: 0 | BH32: 0 | BI32: 0 | BJ32: 0 | BK32: 0 | BL32: -76110 | BM32: 0 | BN32: 0 | BO32: 0 | BP32: 0 | BQ32: 0 | BR32: 0 | BS32: =SUM(ERP_8[[#This Row],[2026 AP01]:[2026 AP12]]) -> -76110
A33: N-ERP-505 | B33: Dougherty, Chris_CONTRACTORS_IT-CTR0132-OT-US-00/iERP | D33: =_xlfn.TEXTJOIN("_",FALSE,E33,ERP_8[[#This Row],[Expense Category]],ERP_8[[#This Row],[Project Code*]]) -> Dougherty, Chris_CONTRACTORS_IT-CTR0132-OT-US-00/iERP | E33: Dougherty, Chris | G33: ERP | H33: Dougherty, Chris | I33: Dougherty, Chris | J33: Maguire, Karla | K33: CONTRACTORS | L33: iERP Reclass - 2026 SAP Max Attention Days | O33: IT-CTR0132-OT-US-00/iERP | Q33: 9501158603 | S33: None | V33: =-91332+91332 -> 0 | W33: 0 | AD33: 0 | AE33: 0 | AG33: 0 | AH33: 0 | AI33: 0 | AJ33: 0 | AL33: =SUM(Z33:AK33) -> 0 | AM33: =ERP_8[[#This Row],[2026 Working Total]]-ERP_8[[#This Row],[LE2 Final Submission]] -> 0 | AN33: 0 | AO33: =$AE33 - $AN33 -> 0 | AP33: =SUM(ERP_8[[#This Row],[AP01]:[AP07]])-SUM(ERP_8[[#This Row],[AP01 LE2]:[AP07 LE2]]) -> 0 | AR33: =ERP_8[[#This Row],[2026 Working Total to Budget/LE]]-ERP_8[[#This Row],[Giveback]] -> 0 | AW33: 0 | AX33: 0 | AY33: 0 | AZ33: 0 | BA33: 0 | BB33: 0 | BC33: 0 | BD33: 0 | BF33: 0 | BG33: 0 | BH33: 0 | BI33: 0 | BJ33: 0 | BK33: 0 | BL33: -91332 | BM33: 0 | BN33: 0 | BO33: 0 | BP33: 0 | BQ33: 0 | BR33: 0 | BS33: =SUM(ERP_8[[#This Row],[2026 AP01]:[2026 AP12]]) -> -91332
A34: N-ERP-506 | B34: Dougherty, Chris_CONTRACTORS_IT-CTR0132-OT-US-00/S4 Innovation | D34: =_xlfn.TEXTJOIN("_",FALSE,E34,ERP_8[[#This Row],[Expense Category]],ERP_8[[#This Row],[Project Code*]]) -> Dougherty, Chris_CONTRACTORS_IT-CTR0132-OT-US-00/S4 Innovation | E34: Dougherty, Chris | G34: ERP | H34: Dougherty, Chris | I34: Dougherty, Chris | J34: Maguire, Karla | K34: CONTRACTORS | L34: S4 Innovation Reclass - 2026 SAP Max Attention Days | O34: IT-CTR0132-OT-US-00/S4 Innovation | Q34: 9501158603 | S34: None | V34: =-76110+76110 -> 0 | W34: 0 | AD34: 0 | AE34: 0 | AG34: 0 | AH34: 0 | AI34: 0 | AJ34: 0 | AL34: =SUM(Z34:AK34) -> 0 | AM34: =ERP_8[[#This Row],[2026 Working Total]]-ERP_8[[#This Row],[LE2 Final Submission]] -> 0 | AN34: 0 | AO34: =$AE34 - $AN34 -> 0 | AP34: =SUM(ERP_8[[#This Row],[AP01]:[AP07]])-SUM(ERP_8[[#This Row],[AP01 LE2]:[AP07 LE2]]) -> 0 | AR34: =ERP_8[[#This Row],[2026 Working Total to Budget/LE]]-ERP_8[[#This Row],[Giveback]] -> 0 | AW34: 0 | AX34: 0 | AY34: 0 | AZ34: 0 | BA34: 0 | BB34: 0 | BC34: 0 | BD34: 0 | BF34: 0 | BG34: 0 | BH34: 0 | BI34: 0 | BJ34: 0 | BK34: 0 | BL34: -76110 | BM34: 0 | BN34: 0 | BO34: 0 | BP34: 0 | BQ34: 0 | BR34: 0 | BS34: =SUM(ERP_8[[#This Row],[2026 AP01]:[2026 AP12]]) -> -76110
A35: L-ERP-085 | B35: Dougherty, Chris_CONTRACTORS_IT-CTR0132-OT-US-01 | D35: =_xlfn.TEXTJOIN("_",FALSE,E35,ERP_8[[#This Row],[Expense Category]],ERP_8[[#This Row],[Project Code*]]) -> Dougherty, Chris_CONTRACTORS_IT-CTR0132-OT-US-01 | E35: Dougherty, Chris | G35: ERP | H35: Dougherty, Chris | I35: Dougherty, Chris | J35: Maguire, Karla | K35: CONTRACTORS | L35: Colalborate 360 Reclass - 2026 SAP Max Attention Days | N35: 2321402 | O35: IT-CTR0132-OT-US-01 | Q35: 9501158603 | S35: None | T35: 6/4 CHW - Removed AP06 Forecast as items hit in AP05 | V35: 0 | W35: -76110 | AD35: -76110 | AE35: 0 | AF35: 0 | AG35: 0 | AH35: 0 | AI35: 0 | AJ35: 0 | AK35: 0 | AL35: =SUM(Z35:AK35) -> -76110 | AM35: =ERP_8[[#This Row],[2026 Working Total]]-ERP_8[[#This Row],[LE2 Final Submission]] -> 0 | AN35: 0 | AO35: =$AE35 - $AN35 -> 0 | AP35: =SUM(ERP_8[[#This Row],[AP01]:[AP07]])-SUM(ERP_8[[#This Row],[AP01 LE2]:[AP07 LE2]]) -> 0 | AR35: =ERP_8[[#This Row],[2026 Working Total to Budget/LE]]-ERP_8[[#This Row],[Giveback]] -> 0 | AY35: -76110 | AZ35: 0 | BA35: 0 | BB35: 0 | BC35: 0 | BD35: 0 | BE35: 0 | BF35: -76110 | BL35: -76110 | BM35: 0 | BN35: 0 | BO35: 0 | BP35: 0 | BQ35: 0 | BR35: 0 | BS35: -76110
A36: L-ERP-086 | B36: Dougherty, Chris_CONTRACTORS_IT-CTR0132-OT-US-02 | D36: =_xlfn.TEXTJOIN("_",FALSE,E36,ERP_8[[#This Row],[Expense Category]],ERP_8[[#This Row],[Project Code*]]) -> Dougherty, Chris_CONTRACTORS_IT-CTR0132-OT-US-02 | E36: Dougherty, Chris | G36: ERP | H36: Dougherty, Chris | I36: Dougherty, Chris | J36: Maguire, Karla | K36: CONTRACTORS | L36: S4 Innovation Reclass - 2026 SAP Max Attention Days | N36: 2321402 | O36: IT-CTR0132-OT-US-02 | Q36: 9501158603 | S36: None | T36: 6/4 CHW - Removed AP06 Forecast as items hit in AP05 | V36: 0 | W36: -136110 | AB36: -60000 | AC36: 0 | AD36: -76110 | AE36: 0 | AF36: 0 | AG36: 0 | AH36: 0 | AI36: 0 | AJ36: 0 | AK36: 0 | AL36: =SUM(Z36:AK36) -> -136110 | AM36: =ERP_8[[#This Row],[2026 Working Total]]-ERP_8[[#This Row],[LE2 Final Submission]] -> 0 | AN36: 0 | AO36: =$AE36 - $AN36 -> 0 | AP36: =SUM(ERP_8[[#This Row],[AP01]:[AP07]])-SUM(ERP_8[[#This Row],[AP01 LE2]:[AP07 LE2]]) -> 0 | AR36: =ERP_8[[#This Row],[2026 Working Total to Budget/LE]]-ERP_8[[#This Row],[Giveback]] -> 0 | AV36: -60000 | AW36: 0 | AX36: 0 | AY36: -76110 | AZ36: 0 | BA36: 0 | BB36: 0 | BC36: 0 | BD36: 0 | BE36: 0 | BF36: -136110 | BI36: -60000 | BJ36: 0 | BK36: 0 | BL36: -76110 | BM36: 0 | BN36: 0 | BO36: 0 | BP36: 0 | BQ36: 0 | BR36: 0 | BS36: -136110
A37: L-ERP-087 | B37: Dougherty, Chris_CONTRACTORS_IT-CTR0132-OT-US-03 | D37: =_xlfn.TEXTJOIN("_",FALSE,E37,ERP_8[[#This Row],[Expense Category]],ERP_8[[#This Row],[Project Code*]]) -> Dougherty, Chris_CONTRACTORS_IT-CTR0132-OT-US-03 | E37: Dougherty, Chris | G37: ERP | H37: Dougherty, Chris | I37: Dougherty, Chris | J37: Maguire, Karla | K37: CONTRACTORS | L37: iERP Reclass - 2026 SAP Max Attention Days | N37: 2321402 | O37: IT-CTR0132-OT-US-03 | Q37: 9501158603 | S37: None | T37: 6/4 CHW - Removed AP06 Forecast as items hit in AP05 | V37: 0 | W37: -91332 | AD37: -91332 | AE37: 0 | AF37: 0 | AG37: 0 | AH37: 0 | AI37: 0 | AJ37: 0 | AK37: 0 | AL37: =SUM(Z37:AK37) -> -91332 | AM37: =ERP_8[[#This Row],[2026 Working Total]]-ERP_8[[#This Row],[LE2 Final Submission]] -> 0 | AN37: 0 | AO37: =$AE37 - $AN37 -> 0 | AP37: =SUM(ERP_8[[#This Row],[AP01]:[AP07]])-SUM(ERP_8[[#This Row],[AP01 LE2]:[AP07 LE2]]) -> 0 | AR37: =ERP_8[[#This Row],[2026 Working Total to Budget/LE]]-ERP_8[[#This Row],[Giveback]] -> 0 | AY37: -91332 | AZ37: 0 | BA37: 0 | BB37: 0 | BC37: 0 | BD37: 0 | BE37: 0 | BF37: -91332 | BL37: -91332 | BM37: 0 | BN37: 0 | BO37: 0 | BP37: 0 | BQ37: 0 | BR37: 0 | BS37: -91332
A38: L-ERP-088 | B38: Dougherty, Chris_CONTRACTORS_IT-CTR0132-OT-US-04 | D38: =_xlfn.TEXTJOIN("_",FALSE,E38,ERP_8[[#This Row],[Expense Category]],ERP_8[[#This Row],[Project Code*]]) -> Dougherty, Chris_CONTRACTORS_IT-CTR0132-OT-US-04 | E38: Dougherty, Chris | G38: ERP | H38: Dougherty, Chris | I38: Dougherty, Chris | J38: Maguire, Karla | K38: CONTRACTORS | L38: BDC Reclass - 2026 SAP Max Attention Days | N38: 2321402 | O38: IT-CTR0132-OT-US-04 | Q38: 9501158603 | S38: None | T38: 6/4 CHW - Removed AP06 Forecast as items hit in AP05 | V38: 0 | W38: -213108 | AD38: -213108 | AE38: 0 | AF38: 0 | AG38: 0 | AH38: 0 | AI38: 0 | AJ38: 0 | AK38: 0 | AL38: =SUM(Z38:AK38) -> -213108 | AM38: =ERP_8[[#This Row],[2026 Working Total]]-ERP_8[[#This Row],[LE2 Final Submission]] -> 0 | AN38: 0 | AO38: =$AE38 - $AN38 -> 0 | AP38: =SUM(ERP_8[[#This Row],[AP01]:[AP07]])-SUM(ERP_8[[#This Row],[AP01 LE2]:[AP07 LE2]]) -> 0 | AR38: =ERP_8[[#This Row],[2026 Working Total to Budget/LE]]-ERP_8[[#This Row],[Giveback]] -> 0 | AY38: -213108 | AZ38: 0 | BA38: 0 | BB38: 0 | BC38: 0 | BD38: 0 | BE38: 0 | BF38: -213108 | BL38: -213108 | BM38: 0 | BN38: 0 | BO38: 0 | BP38: 0 | BQ38: 0 | BR38: 0 | BS38: -213108
A39: N-ERP-606 | B39: Meadows, Leslie_CONTRACTORS_IT-CTR0140-OT-US-00 | D39: =_xlfn.TEXTJOIN("_",FALSE,E39,ERP_8[[#This Row],[Expense Category]],ERP_8[[#This Row],[Project Code*]]) -> Dougherty, Chris_CONTRACTORS_IT-CTR0140-OT-US-00 | E39: Dougherty, Chris | G39: ERP | H39: Dougherty, Chris | I39: Meadows, Leslie | J39: Maguire, Karla | K39: CONTRACTORS | L39: Tricentis Tosca Professional Services | M39: TRICENTIS USA CORP | N39: 2321403 | O39: IT-CTR0140-OT-US-00 | Q39: 9501021870 | S39: None | T39: 4/28/26 CHW New add to tie-out 0223 to 0317 Planful Extracts 2026 Tricentis Tosca Professional Services has been reduced from $8,000 to $0 by deferring upgrade/optimization work and will be revisited in 2027 | V39: 1 | W39: 0 | AD39: 0 | AE39: 0 | AG39: 0 | AH39: 0 | AI39: 0 | AJ39: 0 | AK39: 0 | AL39: =SUM(Z39:AK39) -> 0 | AM39: =ERP_8[[#This Row],[2026 Working Total]]-ERP_8[[#This Row],[LE2 Final Submission]] -> 0 | AN39: 0 | AO39: =$AE39 - $AN39 -> 0 | AP39: =SUM(ERP_8[[#This Row],[AP01]:[AP07]])-SUM(ERP_8[[#This Row],[AP01 LE2]:[AP07 LE2]]) -> 0 | AR39: =ERP_8[[#This Row],[2026 Working Total to Budget/LE]]-ERP_8[[#This Row],[Giveback]] -> 0 | AW39: 0 | AX39: 0 | AY39: 0 | AZ39: 0 | BA39: 0 | BB39: 0 | BC39: 0 | BD39: 0 | BE39: 0 | BF39: 0 | BG39: 0 | BH39: 0 | BI39: 0 | BJ39: 0 | BK39: 0 | BL39: 0 | BM39: 0 | BN39: 0 | BO39: 0 | BP39: 0 | BQ39: 0 | BR39: 1 | BS39: =SUM(ERP_8[[#This Row],[2026 AP01]:[2026 AP12]]) -> 1
A40: L-ERP-089 | B40: Dougherty, Chris_CONTRACTORS_IT-CTR0147-OG-US-00 | D40: =_xlfn.TEXTJOIN("_",FALSE,E40,ERP_8[[#This Row],[Expense Category]],ERP_8[[#This Row],[Project Code*]]) -> Dougherty, Chris_CONTRACTORS_IT-CTR0147-OG-US-00 | E40: Dougherty, Chris | G40: ERP | H40: Dougherty, Chris | I40: Dougherty, Chris | J40: Maguire, Karla | K40: CONTRACTORS | L40: Accenture: eWM Integration | M40: ACCENTURE LLP | N40: 2321402 | O40: IT-CTR0147-OG-US-00 | Q40: 9501182158 | S40: None | V40: 178000 | W40: 136206.92 | AA40: 53852.77 | AB40: 35563.15 | AC40: 1016.08 | AD40: -9701 | AE40: 0 | AF40: 0 | AG40: 0 | AH40: 0 | AI40: 0 | AJ40: 0 | AK40: 0 | AL40: =SUM(Z40:AK40) -> 80731 | AM40: =ERP_8[[#This Row],[2026 Working Total]]-ERP_8[[#This Row],[LE2 Final Submission]] -> -55475.92 | AN40: 0 | AO40: =$AE40 - $AN40 -> 0 | AP40: =SUM(ERP_8[[#This Row],[AP01]:[AP07]])-SUM(ERP_8[[#This Row],[AP01 LE2]:[AP07 LE2]]) -> -55475.92 | AR40: =ERP_8[[#This Row],[2026 Working Total to Budget/LE]]-ERP_8[[#This Row],[Giveback]] -> -55475.92 | AU40: 53852.77 | AV40: 35563.15 | AW40: 19053 | AX40: 27738 | AZ40: 0 | BA40: 0 | BB40: 0 | BC40: 0 | BD40: 0 | BE40: 0 | BF40: 136206.92 | BH40: 53852.77 | BI40: 35563.15 | BJ40: 29666.67 | BK40: 29666.67 | BL40: 29666.67 | BM40: 0 | BN40: 0 | BO40: 0 | BP40: 0 | BQ40: 0 | BR40: 0 | BS40: 178415.93
